Workbook

Sheet Dashboard
A1: داشبورد عملکرد اپراتورها (SLA)
A3: خلاصه عملکرد بر اساس سرگروه (Team Lead)
A4: سرگروه | B4: تعداد اپراتور | C4: مجموع سفارشات | D4: میانگین OCT (دقیقه) | E4: میانگین امتیاز
A5: آتنا مالمیر | B5: =COUNTIF('Operators performance'!$E$3:$E$1001,A5) -> 42 | C5: =SUMIF('Operators performance'!$E$3:$E$1001,A5,'Operators performance'!$G$3:$G$1001)+SUMIF('Operators performance'!$E$3:$E$1001,A5,'Operators performance'!$L$3:$L$1001) -> 8361 | D5: =IFERROR((AVERAGEIF('Operators performance'!$E$3:$E$1001,A5,'Operators performance'!$H$3:$H$1001)+AVERAGEIF('Operators performance'!$E$3:$E$1001,A5,'Operators performance'!$M$3:$M$1001))/2,0) -> 28.7375 | E5: =IFERROR((AVERAGEIF('Operators performance'!$E$3:$E$1001,A5,'Operators performance'!$K$3:$K$1001)+AVERAGEIF('Operators performance'!$E$3:$E$1001,A5,'Operators performance'!$P$3:$P$1001))/2,0) -> 2.5297619
A6: امیررضا فلاح | B6: =COUNTIF('Operators performance'!$E$3:$E$1001,A6) -> 32 | C6: =SUMIF('Operators performance'!$E$3:$E$1001,A6,'Operators performance'!$G$3:$G$1001)+SUMIF('Operators performance'!$E$3:$E$1001,A6,'Operators performance'!$L$3:$L$1001) -> 5488 | D6: =IFERROR((AVERAGEIF('Operators performance'!$E$3:$E$1001,A6,'Operators performance'!$H$3:$H$1001)+AVERAGEIF('Operators performance'!$E$3:$E$1001,A6,'Operators performance'!$M$3:$M$1001))/2,0) -> 31.80625 | E6: =IFERROR((AVERAGEIF('Operators performance'!$E$3:$E$1001,A6,'Operators performance'!$K$3:$K$1001)+AVERAGEIF('Operators performance'!$E$3:$E$1001,A6,'Operators performance'!$P$3:$P$1001))/2,0) -> 2.1328125
A7: شاهین شهریاری | B7: =COUNTIF('Operators performance'!$E$3:$E$1001,A7) -> 3 | C7: =SUMIF('Operators performance'!$E$3:$E$1001,A7,'Operators performance'!$G$3:$G$1001)+SUMIF('Operators performance'!$E$3:$E$1001,A7,'Operators performance'!$L$3:$L$1001) -> 46 | D7: =IFERROR((AVERAGEIF('Operators performance'!$E$3:$E$1001,A7,'Operators performance'!$H$3:$H$1001)+AVERAGEIF('Operators performance'!$E$3:$E$1001,A7,'Operators performance'!$M$3:$M$1001))/2,0) -> 22.166667 | E7: =IFERROR((AVERAGEIF('Operators performance'!$E$3:$E$1001,A7,'Operators performance'!$K$3:$K$1001)+AVERAGEIF('Operators performance'!$E$3:$E$1001,A7,'Operators performance'!$P$3:$P$1001))/2,0) -> 1.5
A8: علیرضا زمانیان | B8: =COUNTIF('Operators performance'!$E$3:$E$1001,A8) -> 51 | C8: =SUMIF('Operators performance'!$E$3:$E$1001,A8,'Operators performance'!$G$3:$G$1001)+SUMIF('Operators performance'!$E$3:$E$1001,A8,'Operators performance'!$L$3:$L$1001) -> 12812 | D8: =IFERROR((AVERAGEIF('Operators performance'!$E$3:$E$1001,A8,'Operators performance'!$H$3:$H$1001)+AVERAGEIF('Operators performance'!$E$3:$E$1001,A8,'Operators performance'!$M$3:$M$1001))/2,0) -> 28.392745 | E8: =IFERROR((AVERAGEIF('Operators performance'!$E$3:$E$1001,A8,'Operators performance'!$K$3:$K$1001)+AVERAGEIF('Operators performance'!$E$3:$E$1001,A8,'Operators performance'!$P$3:$P$1001))/2,0) -> 2.8284314
A9: فاطمه دهقانپور | B9: =COUNTIF('Operators performance'!$E$3:$E$1001,A9) -> 44 | C9: =SUMIF('Operators performance'!$E$3:$E$1001,A9,'Operators performance'!$G$3:$G$1001)+SUMIF('Operators performance'!$E$3:$E$1001,A9,'Operators performance'!$L$3:$L$1001) -> 9632 | D9: =IFERROR((AVERAGEIF('Operators performance'!$E$3:$E$1001,A9,'Operators performance'!$H$3:$H$1001)+AVERAGEIF('Operators performance'!$E$3:$E$1001,A9,'Operators performance'!$M$3:$M$1001))/2,0) -> 32.939394 | E9: =IFERROR((AVERAGEIF('Operators performance'!$E$3:$E$1001,A9,'Operators performance'!$K$3:$K$1001)+AVERAGEIF('Operators performance'!$E$3:$E$1001,A9,'Operators performance'!$P$3:$P$1001))/2,0) -> 2.3522727
A10: مریم ایزدی - شاهین شهریاری | B10: =COUNTIF('Operators performance'!$E$3:$E$1001,A10) -> 30 | C10: =SUMIF('Operators performance'!$E$3:$E$1001,A10,'Operators performance'!$G$3:$G$1001)+SUMIF('Operators performance'!$E$3:$E$1001,A10,'Operators performance'!$L$3:$L$1001) -> 5799 | D10: =IFERROR((AVERAGEIF('Operators performance'!$E$3:$E$1001,A10,'Operators performance'!$H$3:$H$1001)+AVERAGEIF('Operators performance'!$E$3:$E$1001,A10,'Operators performance'!$M$3:$M$1001))/2,0) -> 26.475926 | E10: =IFERROR((AVERAGEIF('Operators performance'!$E$3:$E$1001,A10,'Operators performance'!$K$3:$K$1001)+AVERAGEIF('Operators performance'!$E$3:$E$1001,A10,'Operators performance'!$P$3:$P$1001))/2,0) -> 2.5083333
A11: مهدی ایازی | B11: =COUNTIF('Operators performance'!$E$3:$E$1001,A11) -> 29 | C11: =SUMIF('Operators performance'!$E$3:$E$1001,A11,'Operators performance'!$G$3:$G$1001)+SUMIF('Operators performance'!$E$3:$E$1001,A11,'Operators performance'!$L$3:$L$1001) -> 6660 | D11: =IFERROR((AVERAGEIF('Operators performance'!$E$3:$E$1001,A11,'Operators performance'!$H$3:$H$1001)+AVERAGEIF('Operators performance'!$E$3:$E$1001,A11,'Operators performance'!$M$3:$M$1001))/2,0) -> 37.413793 | E11: =IFERROR((AVERAGEIF('Operators performance'!$E$3:$E$1001,A11,'Operators performance'!$K$3:$K$1001)+AVERAGEIF('Operators performance'!$E$3:$E$1001,A11,'Operators performance'!$P$3:$P$1001))/2,0) -> 2.25
A12: مهدی فراهانی | B12: =COUNTIF('Operators performance'!$E$3:$E$1001,A12) -> 45 | C12: =SUMIF('Operators performance'!$E$3:$E$1001,A12,'Operators performance'!$G$3:$G$1001)+SUMIF('Operators performance'!$E$3:$E$1001,A12,'Operators performance'!$L$3:$L$1001) -> 10746 | D12: =IFERROR((AVERAGEIF('Operators performance'!$E$3:$E$1001,A12,'Operators performance'!$H$3:$H$1001)+AVERAGEIF('Operators performance'!$E$3:$E$1001,A12,'Operators performance'!$M$3:$M$1001))/2,0) -> 25.664646 | E12: =IFERROR((AVERAGEIF('Operators performance'!$E$3:$E$1001,A12,'Operators performance'!$K$3:$K$1001)+AVERAGEIF('Operators performance'!$E$3:$E$1001,A12,'Operators performance'!$P$3:$P$1001))/2,0) -> 2.8111111
A13: هومن قضائی | B13: =COUNTIF('Operators performance'!$E$3:$E$1001,A13) -> 6 | C13: =SUMIF('Operators performance'!$E$3:$E$1001,A13,'Operators performance'!$G$3:$G$1001)+SUMIF('Operators performance'!$E$3:$E$1001,A13,'Operators performance'!$L$3:$L$1001) -> 347 | D13: =IFERROR((AVERAGEIF('Operators performance'!$E$3:$E$1001,A13,'Operators performance'!$H$3:$H$1001)+AVERAGEIF('Operators performance'!$E$3:$E$1001,A13,'Operators performance'!$M$3:$M$1001))/2,0) -> 35.166667 | E13: =IFERROR((AVERAGEIF('Operators performance'!$E$3:$E$1001,A13,'Operators performance'!$K$3:$K$1001)+AVERAGEIF('Operators performance'!$E$3:$E$1001,A13,'Operators performance'!$P$3:$P$1001))/2,0) -> 1.4166667
A16: خلاصه عملکرد بر اساس شرکت
A17: شرکت | B17: تعداد اپراتور | C17: مجموع سفارشات | D17: میانگین امتیاز
A18: آرمان | B18: =COUNTIF('Operators performance'!$C$3:$C$1001,A18) -> 1 | C18: =SUMIF('Operators performance'!$C$3:$C$1001,A18,'Operators performance'!$G$3:$G$1001)+SUMIF('Operators performance'!$C$3:$C$1001,A18,'Operators performance'!$L$3:$L$1001) -> 167 | D18: =IFERROR((AVERAGEIF('Operators performance'!$C$3:$C$1001,A18,'Operators performance'!$K$3:$K$1001)+AVERAGEIF('Operators performance'!$C$3:$C$1001,A18,'Operators performance'!$P$3:$P$1001))/2,0) -> 1.25
A19: البرز | B19: =COUNTIF('Operators performance'!$C$3:$C$1001,A19) -> 1 | C19: =SUMIF('Operators performance'!$C$3:$C$1001,A19,'Operators performance'!$G$3:$G$1001)+SUMIF('Operators performance'!$C$3:$C$1001,A19,'Operators performance'!$L$3:$L$1001) -> 162 | D19: =IFERROR((AVERAGEIF('Operators performance'!$C$3:$C$1001,A19,'Operators performance'!$K$3:$K$1001)+AVERAGEIF('Operators performance'!$C$3:$C$1001,A19,'Operators performance'!$P$3:$P$1001))/2,0) -> 1.25
A20: ایران | B20: =COUNTIF('Operators performance'!$C$3:$C$1001,A20) -> 38 | C20: =SUMIF('Operators performance'!$C$3:$C$1001,A20,'Operators performance'!$G$3:$G$1001)+SUMIF('Operators performance'!$C$3:$C$1001,A20,'Operators performance'!$L$3:$L$1001) -> 12601 | D20: =IFERROR((AVERAGEIF('Operators performance'!$C$3:$C$1001,A20,'Operators performance'!$K$3:$K$1001)+AVERAGEIF('Operators performance'!$C$3:$C$1001,A20,'Operators performance'!$P$3:$P$1001))/2,0) -> 3.4210526
A21: تعاون | B21: =COUNTIF('Operators performance'!$C$3:$C$1001,A21) -> 48 | C21: =SUMIF('Operators performance'!$C$3:$C$1001,A21,'Operators performance'!$G$3:$G$1001)+SUMIF('Operators performance'!$C$3:$C$1001,A21,'Operators performance'!$L$3:$L$1001) -> 9625 | D21: =IFERROR((AVERAGEIF('Operators performance'!$C$3:$C$1001,A21,'Operators performance'!$K$3:$K$1001)+AVERAGEIF('Operators performance'!$C$3:$C$1001,A21,'Operators performance'!$P$3:$P$1001))/2,0) -> 2.6145833
A22: دی | B22: =COUNTIF('Operators performance'!$C$3:$C$1001,A22) -> 9 | C22: =SUMIF('Operators performance'!$C$3:$C$1001,A22,'Operators performance'!$G$3:$G$1001)+SUMIF('Operators performance'!$C$3:$C$1001,A22,'Operators performance'!$L$3:$L$1001) -> 1165 | D22: =IFERROR((AVERAGEIF('Operators performance'!$C$3:$C$1001,A22,'Operators performance'!$K$3:$K$1001)+AVERAGEIF('Operators performance'!$C$3:$C$1001,A22,'Operators performance'!$P$3:$P$1001))/2,0) -> 1.5555556
A23: رازی | B23: =COUNTIF('Operators performance'!$C$3:$C$1001,A23) -> 74 | C23: =SUMIF('Operators performance'!$C$3:$C$1001,A23,'Operators performance'!$G$3:$G$1001)+SUMIF('Operators performance'!$C$3:$C$1001,A23,'Operators performance'!$L$3:$L$1001) -> 13849 | D23: =IFERROR((AVERAGEIF('Operators performance'!$C$3:$C$1001,A23,'Operators performance'!$K$3:$K$1001)+AVERAGEIF('Operators performance'!$C$3:$C$1001,A23,'Operators performance'!$P$3:$P$1001))/2,0) -> 2.3581081
A24: سنتر | B24: =COUNTIF('Operators performance'!$C$3:$C$1001,A24) -> 39 | C24: =SUMIF('Operators performance'!$C$3:$C$1001,A24,'Operators performance'!$G$3:$G$1001)+SUMIF('Operators performance'!$C$3:$C$1001,A24,'Operators performance'!$L$3:$L$1001) -> 6192 | D24: =IFERROR((AVERAGEIF('Operators performance'!$C$3:$C$1001,A24,'Operators performance'!$K$3:$K$1001)+AVERAGEIF('Operators performance'!$C$3:$C$1001,A24,'Operators performance'!$P$3:$P$1001))/2,0) -> 2.2628205
A25: سینا | B25: =COUNTIF('Operators performance'!$C$3:$C$1001,A25) -> 58 | C25: =SUMIF('Operators performance'!$C$3:$C$1001,A25,'Operators performance'!$G$3:$G$1001)+SUMIF('Operators performance'!$C$3:$C$1001,A25,'Operators performance'!$L$3:$L$1001) -> 13773 | D25: =IFERROR((AVERAGEIF('Operators performance'!$C$3:$C$1001,A25,'Operators performance'!$K$3:$K$1001)+AVERAGEIF('Operators performance'!$C$3:$C$1001,A25,'Operators performance'!$P$3:$P$1001))/2,0) -> 2.3922414
A26: هوشمند فردا | B26: =COUNTIF('Operators performance'!$C$3:$C$1001,A26) -> 11 | C26: =SUMIF('Operators performance'!$C$3:$C$1001,A26,'Operators performance'!$G$3:$G$1001)+SUMIF('Operators performance'!$C$3:$C$1001,A26,'Operators performance'!$L$3:$L$1001) -> 2202 | D26: =IFERROR((AVERAGEIF('Operators performance'!$C$3:$C$1001,A26,'Operators performance'!$K$3:$K$1001)+AVERAGEIF('Operators performance'!$C$3:$C$1001,A26,'Operators performance'!$P$3:$P$1001))/2,0) -> 2.0909091
A27: پارسیان | B27: =COUNTIF('Operators performance'!$C$3:$C$1001,A27) -> 3 | C27: =SUMIF('Operators performance'!$C$3:$C$1001,A27,'Operators performance'!$G$3:$G$1001)+SUMIF('Operators performance'!$C$3:$C$1001,A27,'Operators performance'!$L$3:$L$1001) -> 155 | D27: =IFERROR((AVERAGEIF('Operators performance'!$C$3:$C$1001,A27,'Operators performance'!$K$3:$K$1001)+AVERAGEIF('Operators performance'!$C$3:$C$1001,A27,'Operators performance'!$P$3:$P$1001))/2,0) -> 1.9166667
A30: خلاصه باگ‌های ثبت‌شده
A31: نوع باگ | B31: تعداد
A32: غیرمالی (N.F.B) | B32: =SUM('Operator Bugs'!$M$2:$M$1002) -> 0
A33: مالی (F.B) | B33: =SUM('Operator Bugs'!$N$2:$N$1002) -> 0
A34: اثرگذار (E.B) | B34: =SUM('Operator Bugs'!$O$2:$O$1002) -> 0
A35: مجموع کل | B35: =SUM('Operator Bugs'!$P$2:$P$1002) -> 0

Sheet Operators performance
A1: اپراتور صدور | B1: Operator | C1: Company | D1: Work Shift | E1: Team Lead | F1: Operators Bug Price | G1: orders_handled | H1: OCT(min) | I1: Issuing Score (out of 5) | J1: Oct Score (out of 5) | K1: average Score | L1: orders_handled | M1: OCT(min) | N1: Issuing Score (out of 5) | O1: Oct Score (out of 5) | P1: average Score | Q1: salary
G2: 1st week-6 | L2: 2nd week-6
A3: آبتین جباری | B3: =TRIM(A3) -> آبتین جباری | C3: =VLOOKUP(B3,Company!B:E,3,0) -> ایران | D3: =VLOOKUP(B3,Company!B:E,2,0) -> صبح | E3: {=IFERROR(INDEX('Team Leads'!$B:$D, MATCH(C3,'Team Leads'!$A:$A,0), MATCH(D3,'Team Leads'!$B$1:$D$1,0)), "")} -> مهدی فراهانی | F3: =VLOOKUP(B3,'Operator Bugs'!A:P,16,0) -> 0 | G3: =IFERROR(VLOOKUP(B3,'6-week1'!B:D,2,0),0) -> 334 | H3: =IFERROR(VLOOKUP(B3,'6-week1'!B:D,3,0),"-") -> 8 | I3: =IF(G3>179,5,IF(G3>149,4,IF(G3>119,3,IF(G3>89,2,IF(G3>59,1,IF(G3<=59,0)))))) -> 5 | J3: =IF(H3>39,1,IF(H3>32,2,IF(H3>26,3,IF(H3>20,4,IF(H3<=20,5))))) -> 5 | K3: =AVERAGE(I3:J3) -> 5 | L3: =IFERROR(VLOOKUP(B3,'6-week2'!B:D,2,0),0) -> 298 | M3: =IFERROR(VLOOKUP(B3,'6-week2'!B:D,3,0),0) -> 8 | N3: =IF(L3>179,5,IF(L3>149,4,IF(L3>119,3,IF(L3>89,2,IF(L3>59,1,IF(L3<=59,0)))))) -> 5 | O3: =IF(M3>39,1,IF(M3>32,2,IF(M3>26,3,IF(M3>20,4,IF(M3<=20,5))))) -> 5 | P3: =AVERAGE(N3,O3) -> 5 | Q3: =IFERROR(VLOOKUP(B3,'6-week1'!B:F,5,0),0) -> 0
A4: رویا زارعی | B4: =TRIM(A4) -> رویا زارعی | C4: =VLOOKUP(B4,Company!B:E,3,0) -> رازی | D4: =VLOOKUP(B4,Company!B:E,2,0) -> صبح | E4: {=IFERROR(INDEX('Team Leads'!$B:$D, MATCH(C4,'Team Leads'!$A:$A,0), MATCH(D4,'Team Leads'!$B$1:$D$1,0)), "")} -> آتنا مالمیر | F4: =VLOOKUP(B4,'Operator Bugs'!A:P,16,0) -> 0 | G4: =IFERROR(VLOOKUP(B4,'6-week1'!B:D,2,0),0) -> 219 | H4: =IFERROR(VLOOKUP(B4,'6-week1'!B:D,3,0),"-") -> 15 | I4: =IF(G4>179,5,IF(G4>149,4,IF(G4>119,3,IF(G4>89,2,IF(G4>59,1,IF(G4<=59,0)))))) -> 5 | J4: =IF(H4>39,1,IF(H4>32,2,IF(H4>26,3,IF(H4>20,4,IF(H4<=20,5))))) -> 5 | K4: =AVERAGE(I4:J4) -> 5 | L4: =IFERROR(VLOOKUP(B4,'6-week2'!B:D,2,0),0) -> 232 | M4: =IFERROR(VLOOKUP(B4,'6-week2'!B:D,3,0),0) -> 13 | N4: =IF(L4>179,5,IF(L4>149,4,IF(L4>119,3,IF(L4>89,2,IF(L4>59,1,IF(L4<=59,0)))))) -> 5 | O4: =IF(M4>39,1,IF(M4>32,2,IF(M4>26,3,IF(M4>20,4,IF(M4<=20,5))))) -> 5 | P4: =AVERAGE(N4,O4) -> 5 | Q4: =IFERROR(VLOOKUP(B4,'6-week1'!B:F,5,0),0) -> 0
A5: علی قناعتی | B5: =TRIM(A5) -> علی قناعتی | C5: =VLOOKUP(B5,Company!B:E,3,0) -> ایران | D5: =VLOOKUP(B5,Company!B:E,2,0) -> عصر | E5: {=IFERROR(INDEX('Team Leads'!$B:$D, MATCH(C5,'Team Leads'!$A:$A,0), MATCH(D5,'Team Leads'!$B$1:$D$1,0)), "")} -> علیرضا زمانیان | F5: =VLOOKUP(B5,'Operator Bugs'!A:P,16,0) -> 0 | G5: =IFERROR(VLOOKUP(B5,'6-week1'!B:D,2,0),0) -> 262 | H5: =IFERROR(VLOOKUP(B5,'6-week1'!B:D,3,0),"-") -> 10 | I5: =IF(G5>179,5,IF(G5>149,4,IF(G5>119,3,IF(G5>89,2,IF(G5>59,1,IF(G5<=59,0)))))) -> 5 | J5: =IF(H5>39,1,IF(H5>32,2,IF(H5>26,3,IF(H5>20,4,IF(H5<=20,5))))) -> 5 | K5: =AVERAGE(I5:J5) -> 5 | L5: =IFERROR(VLOOKUP(B5,'6-week2'!B:D,2,0),0) -> 480 | M5: =IFERROR(VLOOKUP(B5,'6-week2'!B:D,3,0),0) -> 18 | N5: =IF(L5>179,5,IF(L5>149,4,IF(L5>119,3,IF(L5>89,2,IF(L5>59,1,IF(L5<=59,0)))))) -> 5 | O5: =IF(M5>39,1,IF(M5>32,2,IF(M5>26,3,IF(M5>20,4,IF(M5<=20,5))))) -> 5 | P5: =AVERAGE(N5,O5) -> 5 | Q5: =IFERROR(VLOOKUP(B5,'6-week1'!B:F,5,0),0) -> 0
A6: علیرضا حمید نیا | B6: =TRIM(A6) -> علیرضا حمید نیا | C6: =VLOOKUP(B6,Company!B:E,3,0) -> ایران | D6: =VLOOKUP(B6,Company!B:E,2,0) -> عصر | E6: {=IFERROR(INDEX('Team Leads'!$B:$D, MATCH(C6,'Team Leads'!$A:$A,0), MATCH(D6,'Team Leads'!$B$1:$D$1,0)), "")} -> علیرضا زمانیان | F6: =VLOOKUP(B6,'Operator Bugs'!A:P,16,0) -> 0 | G6: =IFERROR(VLOOKUP(B6,'6-week1'!B:D,2,0),0) -> 250 | H6: =IFERROR(VLOOKUP(B6,'6-week1'!B:D,3,0),"-") -> 15 | I6: =IF(G6>179,5,IF(G6>149,4,IF(G6>119,3,IF(G6>89,2,IF(G6>59,1,IF(G6<=59,0)))))) -> 5 | J6: =IF(H6>39,1,IF(H6>32,2,IF(H6>26,3,IF(H6>20,4,IF(H6<=20,5))))) -> 5 | K6: =AVERAGE(I6:J6) -> 5 | L6: =IFERROR(VLOOKUP(B6,'6-week2'!B:D,2,0),0) -> 253 | M6: =IFERROR(VLOOKUP(B6,'6-week2'!B:D,3,0),0) -> 11 | N6: =IF(L6>179,5,IF(L6>149,4,IF(L6>119,3,IF(L6>89,2,IF(L6>59,1,IF(L6<=59,0)))))) -> 5 | O6: =IF(M6>39,1,IF(M6>32,2,IF(M6>26,3,IF(M6>20,4,IF(M6<=20,5))))) -> 5 | P6: =AVERAGE(N6,O6) -> 5 | Q6: =IFERROR(VLOOKUP(B6,'6-week1'!B:F,5,0),0) -> 0
A7: معراج عزیزی | B7: =TRIM(A7) -> معراج عزیزی | C7: =VLOOKUP(B7,Company!B:E,3,0) -> ایران | D7: =VLOOKUP(B7,Company!B:E,2,0) -> عصر | E7: {=IFERROR(INDEX('Team Leads'!$B:$D, MATCH(C7,'Team Leads'!$A:$A,0), MATCH(D7,'Team Leads'!$B$1:$D$1,0)), "")} -> علیرضا زمانیان | F7: =VLOOKUP(B7,'Operator Bugs'!A:P,16,0) -> 0 | G7: =IFERROR(VLOOKUP(B7,'6-week1'!B:D,2,0),0) -> 333 | H7: =IFERROR(VLOOKUP(B7,'6-week1'!B:D,3,0),"-") -> 15 | I7: =IF(G7>179,5,IF(G7>149,4,IF(G7>119,3,IF(G7>89,2,IF(G7>59,1,IF(G7<=59,0)))))) -> 5 | J7: =IF(H7>39,1,IF(H7>32,2,IF(H7>26,3,IF(H7>20,4,IF(H7<=20,5))))) -> 5 | K7: =AVERAGE(I7:J7) -> 5 | L7: =IFERROR(VLOOKUP(B7,'6-week2'!B:D,2,0),0) -> 194 | M7: =IFERROR(VLOOKUP(B7,'6-week2'!B:D,3,0),0) -> 12 | N7: =IF(L7>179,5,IF(L7>149,4,IF(L7>119,3,IF(L7>89,2,IF(L7>59,1,IF(L7<=59,0)))))) -> 5 | O7: =IF(M7>39,1,IF(M7>32,2,IF(M7>26,3,IF(M7>20,4,IF(M7<=20,5))))) -> 5 | P7: =AVERAGE(N7,O7) -> 5 | Q7: =IFERROR(VLOOKUP(B7,'6-week1'!B:F,5,0),0) -> 0
A8: افشین میرزاده | B8: =TRIM(A8) -> افشین میرزاده | C8: =VLOOKUP(B8,Company!B:E,3,0) -> ایران | D8: =VLOOKUP(B8,Company!B:E,2,0) -> صبح | E8: {=IFERROR(INDEX('Team Leads'!$B:$D, MATCH(C8,'Team Leads'!$A:$A,0), MATCH(D8,'Team Leads'!$B$1:$D$1,0)), "")} -> مهدی فراهانی | F8: =VLOOKUP(B8,'Operator Bugs'!A:P,16,0) -> 0 | G8: =IFERROR(VLOOKUP(B8,'6-week1'!B:D,2,0),0) -> 269 | H8: =IFERROR(VLOOKUP(B8,'6-week1'!B:D,3,0),"-") -> 18 | I8: =IF(G8>179,5,IF(G8>149,4,IF(G8>119,3,IF(G8>89,2,IF(G8>59,1,IF(G8<=59,0)))))) -> 5 | J8: =IF(H8>39,1,IF(H8>32,2,IF(H8>26,3,IF(H8>20,4,IF(H8<=20,5))))) -> 5 | K8: =AVERAGE(I8:J8) -> 5 | L8: =IFERROR(VLOOKUP(B8,'6-week2'!B:D,2,0),0) -> 201 | M8: =IFERROR(VLOOKUP(B8,'6-week2'!B:D,3,0),0) -> 24 | N8: =IF(L8>179,5,IF(L8>149,4,IF(L8>119,3,IF(L8>89,2,IF(L8>59,1,IF(L8<=59,0)))))) -> 5 | O8: =IF(M8>39,1,IF(M8>32,2,IF(M8>26,3,IF(M8>20,4,IF(M8<=20,5))))) -> 4 | P8: =AVERAGE(N8,O8) -> 4.5 | Q8: =IFERROR(VLOOKUP(B8,'6-week1'!B:F,5,0),0) -> 0
A9: امیر حسین پزشک پور | B9: =TRIM(A9) -> امیر حسین پزشک پور | C9: =VLOOKUP(B9,Company!B:E,3,0) -> رازی | D9: =VLOOKUP(B9,Company!B:E,2,0) -> صبح | E9: {=IFERROR(INDEX('Team Leads'!$B:$D, MATCH(C9,'Team Leads'!$A:$A,0), MATCH(D9,'Team Leads'!$B$1:$D$1,0)), "")} -> آتنا مالمیر | F9: =VLOOKUP(B9,'Operator Bugs'!A:P,16,0) -> 0 | G9: =IFERROR(VLOOKUP(B9,'6-week1'!B:D,2,0),0) -> 221 | H9: =IFERROR(VLOOKUP(B9,'6-week1'!B:D,3,0),"-") -> 16 | I9: =IF(G9>179,5,IF(G9>149,4,IF(G9>119,3,IF(G9>89,2,IF(G9>59,1,IF(G9<=59,0)))))) -> 5 | J9: =IF(H9>39,1,IF(H9>32,2,IF(H9>26,3,IF(H9>20,4,IF(H9<=20,5))))) -> 5 | K9: =AVERAGE(I9:J9) -> 5 | L9: =IFERROR(VLOOKUP(B9,'6-week2'!B:D,2,0),0) -> 233 | M9: =IFERROR(VLOOKUP(B9,'6-week2'!B:D,3,0),0) -> 22 | N9: =IF(L9>179,5,IF(L9>149,4,IF(L9>119,3,IF(L9>89,2,IF(L9>59,1,IF(L9<=59,0)))))) -> 5 | O9: =IF(M9>39,1,IF(M9>32,2,IF(M9>26,3,IF(M9>20,4,IF(M9<=20,5))))) -> 4 | P9: =AVERAGE(N9,O9) -> 4.5 | Q9: =IFERROR(VLOOKUP(B9,'6-week1'!B:F,5,0),0) -> 0
A10: سارا جاوری | B10: =TRIM(A10) -> سارا جاوری | C10: =VLOOKUP(B10,Company!B:E,3,0) -> ایران | D10: =VLOOKUP(B10,Company!B:E,2,0) -> صبح | E10: {=IFERROR(INDEX('Team Leads'!$B:$D, MATCH(C10,'Team Leads'!$A:$A,0), MATCH(D10,'Team Leads'!$B$1:$D$1,0)), "")} -> مهدی فراهانی | F10: =VLOOKUP(B10,'Operator Bugs'!A:P,16,0) -> 0 | G10: =IFERROR(VLOOKUP(B10,'6-week1'!B:D,2,0),0) -> 269 | H10: =IFERROR(VLOOKUP(B10,'6-week1'!B:D,3,0),"-") -> 19 | I10: =IF(G10>179,5,IF(G10>149,4,IF(G10>119,3,IF(G10>89,2,IF(G10>59,1,IF(G10<=59,0)))))) -> 5 | J10: =IF(H10>39,1,IF(H10>32,2,IF(H10>26,3,IF(H10>20,4,IF(H10<=20,5))))) -> 5 | K10: =AVERAGE(I10:J10) -> 5 | L10: =IFERROR(VLOOKUP(B10,'6-week2'!B:D,2,0),0) -> 258 | M10: =IFERROR(VLOOKUP(B10,'6-week2'!B:D,3,0),0) -> 17 | N10: =IF(L10>179,5,IF(L10>149,4,IF(L10>119,3,IF(L10>89,2,IF(L10>59,1,IF(L10<=59,0)))))) -> 5 | O10: =IF(M10>39,1,IF(M10>32,2,IF(M10>26,3,IF(M10>20,4,IF(M10<=20,5))))) -> 5 | P10: =AVERAGE(N10,O10) -> 5 | Q10: =IFERROR(VLOOKUP(B10,'6-week1'!B:F,5,0),0) -> 0
A11: سارا رسولی | B11: =TRIM(A11) -> سارا رسولی | C11: =VLOOKUP(B11,Company!B:E,3,0) -> رازی | D11: =VLOOKUP(B11,Company!B:E,2,0) -> عصر | E11: {=IFERROR(INDEX('Team Leads'!$B:$D, MATCH(C11,'Team Leads'!$A:$A,0), MATCH(D11,'Team Leads'!$B$1:$D$1,0)), "")} -> امیررضا فلاح | F11: =VLOOKUP(B11,'Operator Bugs'!A:P,16,0) -> 0 | G11: =IFERROR(VLOOKUP(B11,'6-week1'!B:D,2,0),0) -> 235 | H11: =IFERROR(VLOOKUP(B11,'6-week1'!B:D,3,0),"-") -> 16 | I11: =IF(G11>179,5,IF(G11>149,4,IF(G11>119,3,IF(G11>89,2,IF(G11>59,1,IF(G11<=59,0)))))) -> 5 | J11: =IF(H11>39,1,IF(H11>32,2,IF(H11>26,3,IF(H11>20,4,IF(H11<=20,5))))) -> 5 | K11: =AVERAGE(I11:J11) -> 5 | L11: =IFERROR(VLOOKUP(B11,'6-week2'!B:D,2,0),0) -> 283 | M11: =IFERROR(VLOOKUP(B11,'6-week2'!B:D,3,0),0) -> 24 | N11: =IF(L11>179,5,IF(L11>149,4,IF(L11>119,3,IF(L11>89,2,IF(L11>59,1,IF(L11<=59,0)))))) -> 5 | O11: =IF(M11>39,1,IF(M11>32,2,IF(M11>26,3,IF(M11>20,4,IF(M11<=20,5))))) -> 4 | P11: =AVERAGE(N11,O11) -> 4.5 | Q11: =IFERROR(VLOOKUP(B11,'6-week1'!B:F,5,0),0) -> 0
A12: فاطمه بهزادی | B12: =TRIM(A12) -> فاطمه بهزادی | C12: =VLOOKUP(B12,Company!B:E,3,0) -> تعاون | D12: =VLOOKUP(B12,Company!B:E,2,0) -> عصر | E12: {=IFERROR(INDEX('Team Leads'!$B:$D, MATCH(C12,'Team Leads'!$A:$A,0), MATCH(D12,'Team Leads'!$B$1:$D$1,0)), "")} -> علیرضا زمانیان | F12: =VLOOKUP(B12,'Operator Bugs'!A:P,16,0) -> 0 | G12: =IFERROR(VLOOKUP(B12,'6-week1'!B:D,2,0),0) -> 252 | H12: =IFERROR(VLOOKUP(B12,'6-week1'!B:D,3,0),"-") -> 20 | I12: =IF(G12>179,5,IF(G12>149,4,IF(G12>119,3,IF(G12>89,2,IF(G12>59,1,IF(G12<=59,0)))))) -> 5 | J12: =IF(H12>39,1,IF(H12>32,2,IF(H12>26,3,IF(H12>20,4,IF(H12<=20,5))))) -> 5 | K12: =AVERAGE(I12:J12) -> 5 | L12: =IFERROR(VLOOKUP(B12,'6-week2'!B:D,2,0),0) -> 171 | M12: =IFERROR(VLOOKUP(B12,'6-week2'!B:D,3,0),0) -> 17 | N12: =IF(L12>179,5,IF(L12>149,4,IF(L12>119,3,IF(L12>89,2,IF(L12>59,1,IF(L12<=59,0)))))) -> 4 | O12: =IF(M12>39,1,IF(M12>32,2,IF(M12>26,3,IF(M12>20,4,IF(M12<=20,5))))) -> 5 | P12: =AVERAGE(N12,O12) -> 4.5 | Q12: =IFERROR(VLOOKUP(B12,'6-week1'!B:F,5,0),0) -> 0
A13: محمد سعیدیان | B13: =TRIM(A13) -> محمد سعیدیان | C13: =VLOOKUP(B13,Company!B:E,3,0) -> ایران | D13: =VLOOKUP(B13,Company!B:E,2,0) -> عصر | E13: {=IFERROR(INDEX('Team Leads'!$B:$D, MATCH(C13,'Team Leads'!$A:$A,0), MATCH(D13,'Team Leads'!$B$1:$D$1,0)), "")} -> علیرضا زمانیان | F13: =VLOOKUP(B13,'Operator Bugs'!A:P,16,0) -> 0 | G13: =IFERROR(VLOOKUP(B13,'6-week1'!B:D,2,0),0) -> 239 | H13: =IFERROR(VLOOKUP(B13,'6-week1'!B:D,3,0),"-") -> 19 | I13: =IF(G13>179,5,IF(G13>149,4,IF(G13>119,3,IF(G13>89,2,IF(G13>59,1,IF(G13<=59,0)))))) -> 5 | J13: =IF(H13>39,1,IF(H13>32,2,IF(H13>26,3,IF(H13>20,4,IF(H13<=20,5))))) -> 5 | K13: =AVERAGE(I13:J13) -> 5 | L13: =IFERROR(VLOOKUP(B13,'6-week2'!B:D,2,0),0) -> 160 | M13: =IFERROR(VLOOKUP(B13,'6-week2'!B:D,3,0),0) -> 20 | N13: =IF(L13>179,5,IF(L13>149,4,IF(L13>119,3,IF(L13>89,2,IF(L13>59,1,IF(L13<=59,0)))))) -> 4 | O13: =IF(M13>39,1,IF(M13>32,2,IF(M13>26,3,IF(M13>20,4,IF(M13<=20,5))))) -> 5 | P13: =AVERAGE(N13,O13) -> 4.5 | Q13: =IFERROR(VLOOKUP(B13,'6-week1'!B:F,5,0),0) -> 0
A14: مرکز صدور خوش سیرت | نازنین به نظر | B14: =TRIM(A14) -> مرکز صدور خوش سیرت | نازنین به نظر | C14: =VLOOKUP(B14,Company!B:E,3,0) -> سنتر | D14: =VLOOKUP(B14,Company!B:E,2,0) -> صبح | E14: {=IFERROR(INDEX('Team Leads'!$B:$D, MATCH(C14,'Team Leads'!$A:$A,0), MATCH(D14,'Team Leads'!$B$1:$D$1,0)), "")} -> مریم ایزدی - شاهین شهریاری | F14: =VLOOKUP(B14,'Operator Bugs'!A:P,16,0) -> 0 | G14: =IFERROR(VLOOKUP(B14,'6-week1'!B:D,2,0),0) -> 200 | H14: =IFERROR(VLOOKUP(B14,'6-week1'!B:D,3,0),"-") -> 16 | I14: =IF(G14>179,5,IF(G14>149,4,IF(G14>119,3,IF(G14>89,2,IF(G14>59,1,IF(G14<=59,0)))))) -> 5 | J14: =IF(H14>39,1,IF(H14>32,2,IF(H14>26,3,IF(H14>20,4,IF(H14<=20,5))))) -> 5 | K14: =AVERAGE(I14:J14) -> 5 | L14: =IFERROR(VLOOKUP(B14,'6-week2'!B:D,2,0),0) -> 238 | M14: =IFERROR(VLOOKUP(B14,'6-week2'!B:D,3,0),0) -> 15 | N14: =IF(L14>179,5,IF(L14>149,4,IF(L14>119,3,IF(L14>89,2,IF(L14>59,1,IF(L14<=59,0)))))) -> 5 | O14: =IF(M14>39,1,IF(M14>32,2,IF(M14>26,3,IF(M14>20,4,IF(M14<=20,5))))) -> 5 | P14: =AVERAGE(N14,O14) -> 5 | Q14: =IFERROR(VLOOKUP(B14,'6-week1'!B:F,5,0),0) -> 0
... A76: هانیه همتی | B76: =TRIM(A76) -> هانیه همتی | C76: =VLOOKUP(B76,Company!B:E,3,0) -> تعاون | D76: =VLOOKUP(B76,Company!B:E,2,0) -> صبح | E76: {=IFERROR(INDEX('Team Leads'!$B:$D, MATCH(C76,'Team Leads'!$A:$A,0), MATCH(D76,'Team Leads'!$B$1:$D$1,0)), "")} -> مهدی فراهانی | F76: =VLOOKUP(B76,'Operator Bugs'!A:P,16,0) -> 0 | G76: =IFERROR(VLOOKUP(B76,'6-week1'!B:D,2,0),0) -> 138 | H76: =IFERROR(VLOOKUP(B76,'6-week1'!B:D,3,0),"-") -> 23 | I76: =IF(G76>179,5,IF(G76>149,4,IF(G76>119,3,IF(G76>89,2,IF(G76>59,1,IF(G76<=59,0)))))) -> 3 | J76: =IF(H76>39,1,IF(H76>32,2,IF(H76>26,3,IF(H76>20,4,IF(H76<=20,5))))) -> 4 | K76: =AVERAGE(I76:J76) -> 3.5 | L76: =IFERROR(VLOOKUP(B76,'6-week2'!B:D,2,0),0) -> 119 | M76: =IFERROR(VLOOKUP(B76,'6-week2'!B:D,3,0),0) -> 32 | N76: =IF(L76>179,5,IF(L76>149,4,IF(L76>119,3,IF(L76>89,2,IF(L76>59,1,IF(L76<=59,0)))))) -> 2 | O76: =IF(M76>39,1,IF(M76>32,2,IF(M76>26,3,IF(M76>20,4,IF(M76<=20,5))))) -> 3 | P76: =AVERAGE(N76,O76) -> 2.5 | Q76: =IFERROR(VLOOKUP(B76,'6-week1'!B:F,5,0),0) -> 0
B77: مرکز صدور شاه محمدی | شیوا شجاعی | C77: =VLOOKUP(B77,Company!B:E,3,0) -> سنتر | D77: =VLOOKUP(B77,Company!B:E,2,0) -> صبح | E77: {=IFERROR(INDEX('Team Leads'!$B:$D, MATCH(C77,'Team Leads'!$A:$A,0), MATCH(D77,'Team Leads'!$B$1:$D$1,0)), "")} -> مریم ایزدی - شاهین شهریاری | F77: =VLOOKUP(B77,'Operator Bugs'!A:P,16,0) -> 0 | G77: =IFERROR(VLOOKUP(B77,'6-week1'!B:D,2,0),0) -> 123 | H77: =IFERROR(VLOOKUP(B77,'6-week1'!B:D,3,0),"-") -> 24 | I77: =IF(G77>179,5,IF(G77>149,4,IF(G77>119,3,IF(G77>89,2,IF(G77>59,1,IF(G77<=59,0)))))) -> 3 | J77: =IF(H77>39,1,IF(H77>32,2,IF(H77>26,3,IF(H77>20,4,IF(H77<=20,5))))) -> 4 | K77: =AVERAGE(I77:J77) -> 3.5 | L77: =IFERROR(VLOOKUP(B77,'6-week2'!B:D,2,0),0) -> 93 | M77: =IFERROR(VLOOKUP(B77,'6-week2'!B:D,3,0),0) -> 24 | N77: =IF(L77>179,5,IF(L77>149,4,IF(L77>119,3,IF(L77>89,2,IF(L77>59,1,IF(L77<=59,0)))))) -> 2 | O77: =IF(M77>39,1,IF(M77>32,2,IF(M77>26,3,IF(M77>20,4,IF(M77<=20,5))))) -> 4 | P77: =AVERAGE(N77,O77) -> 3 | Q77: =IFERROR(VLOOKUP(B77,'6-week1'!B:F,5,0),0) -> 0
A78: آتنا محبی | B78: =TRIM(A78) -> آتنا محبی | C78: =VLOOKUP(B78,Company!B:E,3,0) -> ایران | D78: =VLOOKUP(B78,Company!B:E,2,0) -> عصر | E78: {=IFERROR(INDEX('Team Leads'!$B:$D, MATCH(C78,'Team Leads'!$A:$A,0), MATCH(D78,'Team Leads'!$B$1:$D$1,0)), "")} -> علیرضا زمانیان | F78: =VLOOKUP(B78,'Operator Bugs'!A:P,16,0) -> 0 | G78: =IFERROR(VLOOKUP(B78,'6-week1'!B:D,2,0),0) -> 147 | H78: =IFERROR(VLOOKUP(B78,'6-week1'!B:D,3,0),"-") -> 32 | I78: =IF(G78>179,5,IF(G78>149,4,IF(G78>119,3,IF(G78>89,2,IF(G78>59,1,IF(G78<=59,0)))))) -> 3 | J78: =IF(H78>39,1,IF(H78>32,2,IF(H78>26,3,IF(H78>20,4,IF(H78<=20,5))))) -> 3 | K78: =AVERAGE(I78:J78) -> 3 | L78: =IFERROR(VLOOKUP(B78,'6-week2'!B:D,2,0),0) -> 175 | M78: =IFERROR(VLOOKUP(B78,'6-week2'!B:D,3,0),0) -> 31 | N78: =IF(L78>179,5,IF(L78>149,4,IF(L78>119,3,IF(L78>89,2,IF(L78>59,1,IF(L78<=59,0)))))) -> 4 | O78: =IF(M78>39,1,IF(M78>32,2,IF(M78>26,3,IF(M78>20,4,IF(M78<=20,5))))) -> 3 | P78: =AVERAGE(N78,O78) -> 3.5 | Q78: =IFERROR(VLOOKUP(B78,'6-week1'!B:F,5,0),0) -> 0
A79: آرین بحیرایی | B79: =TRIM(A79) -> آرین بحیرایی | C79: =VLOOKUP(B79,Company!B:E,3,0) -> تعاون | D79: =VLOOKUP(B79,Company!B:E,2,0) -> صبح | E79: {=IFERROR(INDEX('Team Leads'!$B:$D, MATCH(C79,'Team Leads'!$A:$A,0), MATCH(D79,'Team Leads'!$B$1:$D$1,0)), "")} -> مهدی فراهانی | F79: =VLOOKUP(B79,'Operator Bugs'!A:P,16,0) -> 0 | G79: =IFERROR(VLOOKUP(B79,'6-week1'!B:D,2,0),0) -> 68 | H79: =IFERROR(VLOOKUP(B79,'6-week1'!B:D,3,0),"-") -> 18 | I79: =IF(G79>179,5,IF(G79>149,4,IF(G79>119,3,IF(G79>89,2,IF(G79>59,1,IF(G79<=59,0)))))) -> 1 | J79: =IF(H79>39,1,IF(H79>32,2,IF(H79>26,3,IF(H79>20,4,IF(H79<=20,5))))) -> 5 | K79: =AVERAGE(I79:J79) -> 3 | L79: =IFERROR(VLOOKUP(B79,'6-week2'!B:D,2,0),0) -> 10 | M79: =IFERROR(VLOOKUP(B79,'6-week2'!B:D,3,0),0) -> 15 | N79: =IF(L79>179,5,IF(L79>149,4,IF(L79>119,3,IF(L79>89,2,IF(L79>59,1,IF(L79<=59,0)))))) -> 0 | O79: =IF(M79>39,1,IF(M79>32,2,IF(M79>26,3,IF(M79>20,4,IF(M79<=20,5))))) -> 5 | P79: =AVERAGE(N79,O79) -> 2.5 | Q79: =IFERROR(VLOOKUP(B79,'6-week1'!B:F,5,0),0) -> 0
A80: آمنه رنجبری | B80: =TRIM(A80) -> آمنه رنجبری | C80: =VLOOKUP(B80,Company!B:E,3,0) -> ایران | D80: =VLOOKUP(B80,Company!B:E,2,0) -> عصر | E80: {=IFERROR(INDEX('Team Leads'!$B:$D, MATCH(C80,'Team Leads'!$A:$A,0), MATCH(D80,'Team Leads'!$B$1:$D$1,0)), "")} -> علیرضا زمانیان | F80: =VLOOKUP(B80,'Operator Bugs'!A:P,16,0) -> 0 | G80: =IFERROR(VLOOKUP(B80,'6-week1'!B:D,2,0),0) -> 92 | H80: =IFERROR(VLOOKUP(B80,'6-week1'!B:D,3,0),"-") -> 26 | I80: =IF(G80>179,5,IF(G80>149,4,IF(G80>119,3,IF(G80>89,2,IF(G80>59,1,IF(G80<=59,0)))))) -> 2 | J80: =IF(H80>39,1,IF(H80>32,2,IF(H80>26,3,IF(H80>20,4,IF(H80<=20,5))))) -> 4 | K80: =AVERAGE(I80:J80) -> 3 | L80: =IFERROR(VLOOKUP(B80,'6-week2'!B:D,2,0),0) -> 100 | M80: =IFERROR(VLOOKUP(B80,'6-week2'!B:D,3,0),0) -> 23 | N80: =IF(L80>179,5,IF(L80>149,4,IF(L80>119,3,IF(L80>89,2,IF(L80>59,1,IF(L80<=59,0)))))) -> 2 | O80: =IF(M80>39,1,IF(M80>32,2,IF(M80>26,3,IF(M80>20,4,IF(M80<=20,5))))) -> 4 | P80: =AVERAGE(N80,O80) -> 3 | Q80: =IFERROR(VLOOKUP(B80,'6-week1'!B:F,5,0),0) -> 0
A81: تینا مختاری | B81: =TRIM(A81) -> تینا مختاری | C81: =VLOOKUP(B81,Company!B:E,3,0) -> رازی | D81: =VLOOKUP(B81,Company!B:E,2,0) -> عصر | E81: {=IFERROR(INDEX('Team Leads'!$B:$D, MATCH(C81,'Team Leads'!$A:$A,0), MATCH(D81,'Team Leads'!$B$1:$D$1,0)), "")} -> امیررضا فلاح | F81: =VLOOKUP(B81,'Operator Bugs'!A:P,16,0) -> 0 | G81: =IFERROR(VLOOKUP(B81,'6-week1'!B:D,2,0),0) -> 191 | H81: =IFERROR(VLOOKUP(B81,'6-week1'!B:D,3,0),"-") -> 56 | I81: =IF(G81>179,5,IF(G81>149,4,IF(G81>119,3,IF(G81>89,2,IF(G81>59,1,IF(G81<=59,0)))))) -> 5 | J81: =IF(H81>39,1,IF(H81>32,2,IF(H81>26,3,IF(H81>20,4,IF(H81<=20,5))))) -> 1 | K81: =AVERAGE(I81:J81) -> 3 | L81: =IFERROR(VLOOKUP(B81,'6-week2'!B:D,2,0),0) -> 149 | M81: =IFERROR(VLOOKUP(B81,'6-week2'!B:D,3,0),0) -> 22 | N81: =IF(L81>179,5,IF(L81>149,4,IF(L81>119,3,IF(L81>89,2,IF(L81>59,1,IF(L81<=59,0)))))) -> 3 | O81: =IF(M81>39,1,IF(M81>32,2,IF(M81>26,3,IF(M81>20,4,IF(M81<=20,5))))) -> 4 | P81: =AVERAGE(N81,O81) -> 3.5 | Q81: =IFERROR(VLOOKUP(B81,'6-week1'!B:F,5,0),0) -> 0
A82: حسن خادمی | B82: =TRIM(A82) -> حسن خادمی | C82: =VLOOKUP(B82,Company!B:E,3,0) -> سینا | D82: =VLOOKUP(B82,Company!B:E,2,0) -> صبح | E82: {=IFERROR(INDEX('Team Leads'!$B:$D, MATCH(C82,'Team Leads'!$A:$A,0), MATCH(D82,'Team Leads'!$B$1:$D$1,0)), "")} -> فاطمه دهقانپور | F82: =VLOOKUP(B82,'Operator Bugs'!A:P,16,0) -> 0 | G82: =IFERROR(VLOOKUP(B82,'6-week1'!B:D,2,0),0) -> 118 | H82: =IFERROR(VLOOKUP(B82,'6-week1'!B:D,3,0),"-") -> 25 | I82: =IF(G82>179,5,IF(G82>149,4,IF(G82>119,3,IF(G82>89,2,IF(G82>59,1,IF(G82<=59,0)))))) -> 2 | J82: =IF(H82>39,1,IF(H82>32,2,IF(H82>26,3,IF(H82>20,4,IF(H82<=20,5))))) -> 4 | K82: =AVERAGE(I82:J82) -> 3 | L82: =IFERROR(VLOOKUP(B82,'6-week2'!B:D,2,0),0) -> 121 | M82: =IFERROR(VLOOKUP(B82,'6-week2'!B:D,3,0),0) -> 21 | N82: =IF(L82>179,5,IF(L82>149,4,IF(L82>119,3,IF(L82>89,2,IF(L82>59,1,IF(L82<=59,0)))))) -> 3 | O82: =IF(M82>39,1,IF(M82>32,2,IF(M82>26,3,IF(M82>20,4,IF(M82<=20,5))))) -> 4 | P82: =AVERAGE(N82,O82) -> 3.5 | Q82: =IFERROR(VLOOKUP(B82,'6-week1'!B:F,5,0),0) -> 0
A83: حسین بهزادی مقدم | B83: =TRIM(A83) -> حسین بهزادی مقدم | C83: =VLOOKUP(B83,Company!B:E,3,0) -> رازی | D83: =VLOOKUP(B83,Company!B:E,2,0) -> عصر | E83: {=IFERROR(INDEX('Team Leads'!$B:$D, MATCH(C83,'Team Leads'!$A:$A,0), MATCH(D83,'Team Leads'!$B$1:$D$1,0)), "")} -> امیررضا فلاح | F83: =VLOOKUP(B83,'Operator Bugs'!A:P,16,0) -> 0 | G83: =IFERROR(VLOOKUP(B83,'6-week1'!B:D,2,0),0) -> 69 | H83: =IFERROR(VLOOKUP(B83,'6-week1'!B:D,3,0),"-") -> 19 | I83: =IF(G83>179,5,IF(G83>149,4,IF(G83>119,3,IF(G83>89,2,IF(G83>59,1,IF(G83<=59,0)))))) -> 1 | J83: =IF(H83>39,1,IF(H83>32,2,IF(H83>26,3,IF(H83>20,4,IF(H83<=20,5))))) -> 5 | K83: =AVERAGE(I83:J83) -> 3 | L83: =IFERROR(VLOOKUP(B83,'6-week2'!B:D,2,0),0) -> 63 | M83: =IFERROR(VLOOKUP(B83,'6-week2'!B:D,3,0),0) -> 21 | N83: =IF(L83>179,5,IF(L83>149,4,IF(L83>119,3,IF(L83>89,2,IF(L83>59,1,IF(L83<=59,0)))))) -> 1 | O83: =IF(M83>39,1,IF(M83>32,2,IF(M83>26,3,IF(M83>20,4,IF(M83<=20,5))))) -> 4 | P83: =AVERAGE(N83,O83) -> 2.5 | Q83: =IFERROR(VLOOKUP(B83,'6-week1'!B:F,5,0),0) -> 0
A84: ریحانه کمالی | B84: =TRIM(A84) -> ریحانه کمالی | C84: =VLOOKUP(B84,Company!B:E,3,0) -> ایران | D84: =VLOOKUP(B84,Company!B:E,2,0) -> صبح | E84: {=IFERROR(INDEX('Team Leads'!$B:$D, MATCH(C84,'Team Leads'!$A:$A,0), MATCH(D84,'Team Leads'!$B$1:$D$1,0)), "")} -> مهدی فراهانی | F84: =VLOOKUP(B84,'Operator Bugs'!A:P,16,0) -> 0 | G84: =IFERROR(VLOOKUP(B84,'6-week1'!B:D,2,0),0) -> 97 | H84: =IFERROR(VLOOKUP(B84,'6-week1'!B:D,3,0),"-") -> 25 | I84: =IF(G84>179,5,IF(G84>149,4,IF(G84>119,3,IF(G84>89,2,IF(G84>59,1,IF(G84<=59,0)))))) -> 2 | J84: =IF(H84>39,1,IF(H84>32,2,IF(H84>26,3,IF(H84>20,4,IF(H84<=20,5))))) -> 4 | K84: =AVERAGE(I84:J84) -> 3 | L84: =IFERROR(VLOOKUP(B84,'6-week2'!B:D,2,0),0) -> 196 | M84: =IFERROR(VLOOKUP(B84,'6-week2'!B:D,3,0),0) -> 27 | N84: =IF(L84>179,5,IF(L84>149,4,IF(L84>119,3,IF(L84>89,2,IF(L84>59,1,IF(L84<=59,0)))))) -> 5 | O84: =IF(M84>39,1,IF(M84>32,2,IF(M84>26,3,IF(M84>20,4,IF(M84<=20,5))))) -> 3 | P84: =AVERAGE(N84,O84) -> 4 | Q84: =IFERROR(VLOOKUP(B84,'6-week1'!B:F,5,0),0) -> 0
A85: زهرا اسماعیلی | B85: =TRIM(A85) -> زهرا اسماعیلی | C85: =VLOOKUP(B85,Company!B:E,3,0) -> رازی | D85: =VLOOKUP(B85,Company!B:E,2,0) -> صبح | E85: {=IFERROR(INDEX('Team Leads'!$B:$D, MATCH(C85,'Team Leads'!$A:$A,0), MATCH(D85,'Team Leads'!$B$1:$D$1,0)), "")} -> آتنا مالمیر | F85: =VLOOKUP(B85,'Operator Bugs'!A:P,16,0) -> 0 | G85: =IFERROR(VLOOKUP(B85,'6-week1'!B:D,2,0),0) -> 137 | H85: =IFERROR(VLOOKUP(B85,'6-week1'!B:D,3,0),"-") -> 27 | I85: =IF(G85>179,5,IF(G85>149,4,IF(G85>119,3,IF(G85>89,2,IF(G85>59,1,IF(G85<=59,0)))))) -> 3 | J85: =IF(H85>39,1,IF(H85>32,2,IF(H85>26,3,IF(H85>20,4,IF(H85<=20,5))))) -> 3 | K85: =AVERAGE(I85:J85) -> 3 | L85: =IFERROR(VLOOKUP(B85,'6-week2'!B:D,2,0),0) -> 187 | M85: =IFERROR(VLOOKUP(B85,'6-week2'!B:D,3,0),0) -> 20 | N85: =IF(L85>179,5,IF(L85>149,4,IF(L85>119,3,IF(L85>89,2,IF(L85>59,1,IF(L85<=59,0)))))) -> 5 | O85: =IF(M85>39,1,IF(M85>32,2,IF(M85>26,3,IF(M85>20,4,IF(M85<=20,5))))) -> 5 | P85: =AVERAGE(N85,O85) -> 5 | Q85: =IFERROR(VLOOKUP(B85,'6-week1'!B:F,5,0),0) -> 0
A86: زهرا سبزیانی داویجانی | B86: =TRIM(A86) -> زهرا سبزیانی داویجانی | C86: =VLOOKUP(B86,Company!B:E,3,0) -> سینا | D86: =VLOOKUP(B86,Company!B:E,2,0) -> صبح | E86: {=IFERROR(INDEX('Team Leads'!$B:$D, MATCH(C86,'Team Leads'!$A:$A,0), MATCH(D86,'Team Leads'!$B$1:$D$1,0)), "")} -> فاطمه دهقانپور | F86: =VLOOKUP(B86,'Operator Bugs'!A:P,16,0) -> 0 | G86: =IFERROR(VLOOKUP(B86,'6-week1'!B:D,2,0),0) -> 186 | H86: =IFERROR(VLOOKUP(B86,'6-week1'!B:D,3,0),"-") -> 57 | I86: =IF(G86>179,5,IF(G86>149,4,IF(G86>119,3,IF(G86>89,2,IF(G86>59,1,IF(G86<=59,0)))))) -> 5 | J86: =IF(H86>39,1,IF(H86>32,2,IF(H86>26,3,IF(H86>20,4,IF(H86<=20,5))))) -> 1 | K86: =AVERAGE(I86:J86) -> 3 | L86: =IFERROR(VLOOKUP(B86,'6-week2'!B:D,2,0),0) -> 203 | M86: =IFERROR(VLOOKUP(B86,'6-week2'!B:D,3,0),0) -> 68 | N86: =IF(L86>179,5,IF(L86>149,4,IF(L86>119,3,IF(L86>89,2,IF(L86>59,1,IF(L86<=59,0)))))) -> 5 | O86: =IF(M86>39,1,IF(M86>32,2,IF(M86>26,3,IF(M86>20,4,IF(M86<=20,5))))) -> 1 | P86: =AVERAGE(N86,O86) -> 3 | Q86: =IFERROR(VLOOKUP(B86,'6-week1'!B:F,5,0),0) -> 0
A87: زهره ذبیحی | B87: =TRIM(A87) -> زهره ذبیحی | C87: =VLOOKUP(B87,Company!B:E,3,0) -> رازی | D87: =VLOOKUP(B87,Company!B:E,2,0) -> صبح | E87: {=IFERROR(INDEX('Team Leads'!$B:$D, MATCH(C87,'Team Leads'!$A:$A,0), MATCH(D87,'Team Leads'!$B$1:$D$1,0)), "")} -> آتنا مالمیر | F87: =VLOOKUP(B87,'Operator Bugs'!A:P,16,0) -> 0 | G87: =IFERROR(VLOOKUP(B87,'6-week1'!B:D,2,0),0) -> 65 | H87: =IFERROR(VLOOKUP(B87,'6-week1'!B:D,3,0),"-") -> 19 | I87: =IF(G87>179,5,IF(G87>149,4,IF(G87>119,3,IF(G87>89,2,IF(G87>59,1,IF(G87<=59,0)))))) -> 1 | J87: =IF(H87>39,1,IF(H87>32,2,IF(H87>26,3,IF(H87>20,4,IF(H87<=20,5))))) -> 5 | K87: =AVERAGE(I87:J87) -> 3 | L87: =IFERROR(VLOOKUP(B87,'6-week2'!B:D,2,0),0) -> 54 | M87: =IFERROR(VLOOKUP(B87,'6-week2'!B:D,3,0),0) -> 21 | N87: =IF(L87>179,5,IF(L87>149,4,IF(L87>119,3,IF(L87>89,2,IF(L87>59,1,IF(L87<=59,0)))))) -> 0 | O87: =IF(M87>39,1,IF(M87>32,2,IF(M87>26,3,IF(M87>20,4,IF(M87<=20,5))))) -> 4 | P87: =AVERAGE(N87,O87) -> 2 | Q87: =IFERROR(VLOOKUP(B87,'6-week1'!B:F,5,0),0) -> 0
A88: زیبا زارعی | B88: =TRIM(A88) -> زیبا زارعی | C88: =VLOOKUP(B88,Company!B:E,3,0) -> تعاون | D88: =VLOOKUP(B88,Company!B:E,2,0) -> عصر | E88: {=IFERROR(INDEX('Team Leads'!$B:$D, MATCH(C88,'Team Leads'!$A:$A,0), MATCH(D88,'Team Leads'!$B$1:$D$1,0)), "")} -> علیرضا زمانیان | F88: =VLOOKUP(B88,'Operator Bugs'!A:P,16,0) -> 0 | G88: =IFERROR(VLOOKUP(B88,'6-week1'!B:D,2,0),0) -> 138 | H88: =IFERROR(VLOOKUP(B88,'6-week1'!B:D,3,0),"-") -> 28 | I88: =IF(G88>179,5,IF(G88>149,4,IF(G88>119,3,IF(G88>89,2,IF(G88>59,1,IF(G88<=59,0)))))) -> 3 | J88: =IF(H88>39,1,IF(H88>32,2,IF(H88>26,3,IF(H88>20,4,IF(H88<=20,5))))) -> 3 | K88: =AVERAGE(I88:J88) -> 3 | L88: =IFERROR(VLOOKUP(B88,'6-week2'!B:D,2,0),0) -> 157 | M88: =IFERROR(VLOOKUP(B88,'6-week2'!B:D,3,0),0) -> 25 | N88: =IF(L88>179,5,IF(L88>149,4,IF(L88>119,3,IF(L88>89,2,IF(L88>59,1,IF(L88<=59,0)))))) -> 4 | O88: =IF(M88>39,1,IF(M88>32,2,IF(M88>26,3,IF(M88>20,4,IF(M88<=20,5))))) -> 4 | P88: =AVERAGE(N88,O88) -> 4 | Q88: =IFERROR(VLOOKUP(B88,'6-week1'!B:F,5,0),0) -> 0
A89: سهراب ایروانی | B89: =TRIM(A89) -> سهراب ایروانی | C89: =VLOOKUP(B89,Company!B:E,3,0) -> تعاون | D89: =VLOOKUP(B89,Company!B:E,2,0) -> عصر | E89: {=IFERROR(INDEX('Team Leads'!$B:$D, MATCH(C89,'Team Leads'!$A:$A,0), MATCH(D89,'Team Leads'!$B$1:$D$1,0)), "")} -> علیرضا زمانیان | F89: =VLOOKUP(B89,'Operator Bugs'!A:P,16,0) -> 0 | G89: =IFERROR(VLOOKUP(B89,'6-week1'!B:D,2,0),0) -> 166 | H89: =IFERROR(VLOOKUP(B89,'6-week1'!B:D,3,0),"-") -> 38 | I89: =IF(G89>179,5,IF(G89>149,4,IF(G89>119,3,IF(G89>89,2,IF(G89>59,1,IF(G89<=59,0)))))) -> 4 | J89: =IF(H89>39,1,IF(H89>32,2,IF(H89>26,3,IF(H89>20,4,IF(H89<=20,5))))) -> 2 | K89: =AVERAGE(I89:J89) -> 3 | L89: =IFERROR(VLOOKUP(B89,'6-week2'!B:D,2,0),0) -> 213 | M89: =IFERROR(VLOOKUP(B89,'6-week2'!B:D,3,0),0) -> 17 | N89: =IF(L89>179,5,IF(L89>149,4,IF(L89>119,3,IF(L89>89,2,IF(L89>59,1,IF(L89<=59,0)))))) -> 5 | O89: =IF(M89>39,1,IF(M89>32,2,IF(M89>26,3,IF(M89>20,4,IF(M89<=20,5))))) -> 5 | P89: =AVERAGE(N89,O89) -> 5 | Q89: =IFERROR(VLOOKUP(B89,'6-week1'!B:F,5,0),0) -> 0
... A132: یلدا نعمتی | B132: =TRIM(A132) -> یلدا نعمتی | C132: =VLOOKUP(B132,Company!B:E,3,0) -> سینا | D132: =VLOOKUP(B132,Company!B:E,2,0) -> صبح | E132: {=IFERROR(INDEX('Team Leads'!$B:$D, MATCH(C132,'Team Leads'!$A:$A,0), MATCH(D132,'Team Leads'!$B$1:$D$1,0)), "")} -> فاطمه دهقانپور | F132: =VLOOKUP(B132,'Operator Bugs'!A:P,16,0) -> 0 | G132: =IFERROR(VLOOKUP(B132,'6-week1'!B:D,2,0),0) -> 146 | H132: =IFERROR(VLOOKUP(B132,'6-week1'!B:D,3,0),"-") -> 35 | I132: =IF(G132>179,5,IF(G132>149,4,IF(G132>119,3,IF(G132>89,2,IF(G132>59,1,IF(G132<=59,0)))))) -> 3 | J132: =IF(H132>39,1,IF(H132>32,2,IF(H132>26,3,IF(H132>20,4,IF(H132<=20,5))))) -> 2 | K132: =AVERAGE(I132:J132) -> 2.5 | L132: =IFERROR(VLOOKUP(B132,'6-week2'!B:D,2,0),0) -> 175 | M132: =IFERROR(VLOOKUP(B132,'6-week2'!B:D,3,0),0) -> 36 | N132: =IF(L132>179,5,IF(L132>149,4,IF(L132>119,3,IF(L132>89,2,IF(L132>59,1,IF(L132<=59,0)))))) -> 4 | O132: =IF(M132>39,1,IF(M132>32,2,IF(M132>26,3,IF(M132>20,4,IF(M132<=20,5))))) -> 2 | P132: =AVERAGE(N132,O132) -> 3 | Q132: =IFERROR(VLOOKUP(B132,'6-week1'!B:F,5,0),0) -> 0
B133: مرکز صدور رضوانی | امیرحسین صابر | C133: =VLOOKUP(B133,Company!B:E,3,0) -> سنتر | D133: =VLOOKUP(B133,Company!B:E,2,0) -> صبح | E133: {=IFERROR(INDEX('Team Leads'!$B:$D, MATCH(C133,'Team Leads'!$A:$A,0), MATCH(D133,'Team Leads'!$B$1:$D$1,0)), "")} -> مریم ایزدی - شاهین شهریاری | F133: =VLOOKUP(B133,'Operator Bugs'!A:P,16,0) -> 0 | G133: =IFERROR(VLOOKUP(B133,'6-week1'!B:D,2,0),0) -> 85 | H133: =IFERROR(VLOOKUP(B133,'6-week1'!B:D,3,0),"-") -> 23 | I133: =IF(G133>179,5,IF(G133>149,4,IF(G133>119,3,IF(G133>89,2,IF(G133>59,1,IF(G133<=59,0)))))) -> 1 | J133: =IF(H133>39,1,IF(H133>32,2,IF(H133>26,3,IF(H133>20,4,IF(H133<=20,5))))) -> 4 | K133: =AVERAGE(I133:J133) -> 2.5 | L133: =IFERROR(VLOOKUP(B133,'6-week2'!B:D,2,0),0) -> 117 | M133: =IFERROR(VLOOKUP(B133,'6-week2'!B:D,3,0),0) -> 22 | N133: =IF(L133>179,5,IF(L133>149,4,IF(L133>119,3,IF(L133>89,2,IF(L133>59,1,IF(L133<=59,0)))))) -> 2 | O133: =IF(M133>39,1,IF(M133>32,2,IF(M133>26,3,IF(M133>20,4,IF(M133<=20,5))))) -> 4 | P133: =AVERAGE(N133,O133) -> 3 | Q133: =IFERROR(VLOOKUP(B133,'6-week1'!B:F,5,0),0) -> 0
A134: آروین کیخسروی | B134: =TRIM(A134) -> آروین کیخسروی | C134: =VLOOKUP(B134,Company!B:E,3,0) -> رازی | D134: =VLOOKUP(B134,Company!B:E,2,0) -> صبح | E134: {=IFERROR(INDEX('Team Leads'!$B:$D, MATCH(C134,'Team Leads'!$A:$A,0), MATCH(D134,'Team Leads'!$B$1:$D$1,0)), "")} -> آتنا مالمیر | F134: =VLOOKUP(B134,'Operator Bugs'!A:P,16,0) -> 0 | G134: =IFERROR(VLOOKUP(B134,'6-week1'!B:D,2,0),0) -> 54 | H134: =IFERROR(VLOOKUP(B134,'6-week1'!B:D,3,0),"-") -> 25 | I134: =IF(G134>179,5,IF(G134>149,4,IF(G134>119,3,IF(G134>89,2,IF(G134>59,1,IF(G134<=59,0)))))) -> 0 | J134: =IF(H134>39,1,IF(H134>32,2,IF(H134>26,3,IF(H134>20,4,IF(H134<=20,5))))) -> 4 | K134: =AVERAGE(I134:J134) -> 2 | L134: =IFERROR(VLOOKUP(B134,'6-week2'!B:D,2,0),0) -> 97 | M134: =IFERROR(VLOOKUP(B134,'6-week2'!B:D,3,0),0) -> 24 | N134: =IF(L134>179,5,IF(L134>149,4,IF(L134>119,3,IF(L134>89,2,IF(L134>59,1,IF(L134<=59,0)))))) -> 2 | O134: =IF(M134>39,1,IF(M134>32,2,IF(M134>26,3,IF(M134>20,4,IF(M134<=20,5))))) -> 4 | P134: =AVERAGE(N134,O134) -> 3 | Q134: =IFERROR(VLOOKUP(B134,'6-week1'!B:F,5,0),0) -> 0
A135: آزاده محبی | B135: =TRIM(A135) -> آزاده محبی | C135: =VLOOKUP(B135,Company!B:E,3,0) -> ایران | D135: =VLOOKUP(B135,Company!B:E,2,0) -> عصر | E135: {=IFERROR(INDEX('Team Leads'!$B:$D, MATCH(C135,'Team Leads'!$A:$A,0), MATCH(D135,'Team Leads'!$B$1:$D$1,0)), "")} -> علیرضا زمانیان | F135: =VLOOKUP(B135,'Operator Bugs'!A:P,16,0) -> 0 | G135: =IFERROR(VLOOKUP(B135,'6-week1'!B:D,2,0),0) -> 77 | H135: =IFERROR(VLOOKUP(B135,'6-week1'!B:D,3,0),"-") -> 30 | I135: =IF(G135>179,5,IF(G135>149,4,IF(G135>119,3,IF(G135>89,2,IF(G135>59,1,IF(G135<=59,0)))))) -> 1 | J135: =IF(H135>39,1,IF(H135>32,2,IF(H135>26,3,IF(H135>20,4,IF(H135<=20,5))))) -> 3 | K135: =AVERAGE(I135:J135) -> 2 | L135: =IFERROR(VLOOKUP(B135,'6-week2'!B:D,2,0),0) -> 136 | M135: =IFERROR(VLOOKUP(B135,'6-week2'!B:D,3,0),0) -> 31 | N135: =IF(L135>179,5,IF(L135>149,4,IF(L135>119,3,IF(L135>89,2,IF(L135>59,1,IF(L135<=59,0)))))) -> 3 | O135: =IF(M135>39,1,IF(M135>32,2,IF(M135>26,3,IF(M135>20,4,IF(M135<=20,5))))) -> 3 | P135: =AVERAGE(N135,O135) -> 3 | Q135: =IFERROR(VLOOKUP(B135,'6-week1'!B:F,5,0),0) -> 0
A136: الهه دریکوند | B136: =TRIM(A136) -> الهه دریکوند | C136: =VLOOKUP(B136,Company!B:E,3,0) -> ایران | D136: =VLOOKUP(B136,Company!B:E,2,0) -> عصر | E136: {=IFERROR(INDEX('Team Leads'!$B:$D, MATCH(C136,'Team Leads'!$A:$A,0), MATCH(D136,'Team Leads'!$B$1:$D$1,0)), "")} -> علیرضا زمانیان | F136: =VLOOKUP(B136,'Operator Bugs'!A:P,16,0) -> 0 | G136: =IFERROR(VLOOKUP(B136,'6-week1'!B:D,2,0),0) -> 83 | H136: =IFERROR(VLOOKUP(B136,'6-week1'!B:D,3,0),"-") -> 29 | I136: =IF(G136>179,5,IF(G136>149,4,IF(G136>119,3,IF(G136>89,2,IF(G136>59,1,IF(G136<=59,0)))))) -> 1 | J136: =IF(H136>39,1,IF(H136>32,2,IF(H136>26,3,IF(H136>20,4,IF(H136<=20,5))))) -> 3 | K136: =AVERAGE(I136:J136) -> 2 | L136: =IFERROR(VLOOKUP(B136,'6-week2'!B:D,2,0),0) -> 91 | M136: =IFERROR(VLOOKUP(B136,'6-week2'!B:D,3,0),0) -> 30 | N136: =IF(L136>179,5,IF(L136>149,4,IF(L136>119,3,IF(L136>89,2,IF(L136>59,1,IF(L136<=59,0)))))) -> 2 | O136: =IF(M136>39,1,IF(M136>32,2,IF(M136>26,3,IF(M136>20,4,IF(M136<=20,5))))) -> 3 | P136: =AVERAGE(N136,O136) -> 2.5 | Q136: =IFERROR(VLOOKUP(B136,'6-week1'!B:F,5,0),0) -> 0
A137: امیر حسین گل محمدی | B137: =TRIM(A137) -> امیر حسین گل محمدی | C137: =VLOOKUP(B137,Company!B:E,3,0) -> ایران | D137: =VLOOKUP(B137,Company!B:E,2,0) -> صبح | E137: {=IFERROR(INDEX('Team Leads'!$B:$D, MATCH(C137,'Team Leads'!$A:$A,0), MATCH(D137,'Team Leads'!$B$1:$D$1,0)), "")} -> مهدی فراهانی | F137: =VLOOKUP(B137,'Operator Bugs'!A:P,16,0) -> 0 | G137: =IFERROR(VLOOKUP(B137,'6-week1'!B:D,2,0),0) -> 77 | H137: =IFERROR(VLOOKUP(B137,'6-week1'!B:D,3,0),"-") -> 27 | I137: =IF(G137>179,5,IF(G137>149,4,IF(G137>119,3,IF(G137>89,2,IF(G137>59,1,IF(G137<=59,0)))))) -> 1 | J137: =IF(H137>39,1,IF(H137>32,2,IF(H137>26,3,IF(H137>20,4,IF(H137<=20,5))))) -> 3 | K137: =AVERAGE(I137:J137) -> 2 | L137: =IFERROR(VLOOKUP(B137,'6-week2'!B:D,2,0),0) -> 75 | M137: =IFERROR(VLOOKUP(B137,'6-week2'!B:D,3,0),0) -> 23 | N137: =IF(L137>179,5,IF(L137>149,4,IF(L137>119,3,IF(L137>89,2,IF(L137>59,1,IF(L137<=59,0)))))) -> 1 | O137: =IF(M137>39,1,IF(M137>32,2,IF(M137>26,3,IF(M137>20,4,IF(M137<=20,5))))) -> 4 | P137: =AVERAGE(N137,O137) -> 2.5 | Q137: =IFERROR(VLOOKUP(B137,'6-week1'!B:F,5,0),0) -> 0
A138: امیر قربانی | B138: =TRIM(A138) -> امیر قربانی | C138: =VLOOKUP(B138,Company!B:E,3,0) -> رازی | D138: =VLOOKUP(B138,Company!B:E,2,0) -> عصر | E138: {=IFERROR(INDEX('Team Leads'!$B:$D, MATCH(C138,'Team Leads'!$A:$A,0), MATCH(D138,'Team Leads'!$B$1:$D$1,0)), "")} -> امیررضا فلاح | F138: =VLOOKUP(B138,'Operator Bugs'!A:P,16,0) -> 0 | G138: =IFERROR(VLOOKUP(B138,'6-week1'!B:D,2,0),0) -> 59 | H138: =IFERROR(VLOOKUP(B138,'6-week1'!B:D,3,0),"-") -> 24 | I138: =IF(G138>179,5,IF(G138>149,4,IF(G138>119,3,IF(G138>89,2,IF(G138>59,1,IF(G138<=59,0)))))) -> 0 | J138: =IF(H138>39,1,IF(H138>32,2,IF(H138>26,3,IF(H138>20,4,IF(H138<=20,5))))) -> 4 | K138: =AVERAGE(I138:J138) -> 2 | L138: =IFERROR(VLOOKUP(B138,'6-week2'!B:D,2,0),0) -> 64 | M138: =IFERROR(VLOOKUP(B138,'6-week2'!B:D,3,0),0) -> 23 | N138: =IF(L138>179,5,IF(L138>149,4,IF(L138>119,3,IF(L138>89,2,IF(L138>59,1,IF(L138<=59,0)))))) -> 1 | O138: =IF(M138>39,1,IF(M138>32,2,IF(M138>26,3,IF(M138>20,4,IF(M138<=20,5))))) -> 4 | P138: =AVERAGE(N138,O138) -> 2.5 | Q138: =IFERROR(VLOOKUP(B138,'6-week1'!B:F,5,0),0) -> 0
A139: امیرحسین کاروند | B139: =TRIM(A139) -> امیرحسین کاروند | C139: =VLOOKUP(B139,Company!B:E,3,0) -> تعاون | D139: =VLOOKUP(B139,Company!B:E,2,0) -> عصر | E139: {=IFERROR(INDEX('Team Leads'!$B:$D, MATCH(C139,'Team Leads'!$A:$A,0), MATCH(D139,'Team Leads'!$B$1:$D$1,0)), "")} -> علیرضا زمانیان | F139: =VLOOKUP(B139,'Operator Bugs'!A:P,16,0) -> 0 | G139: =IFERROR(VLOOKUP(B139,'6-week1'!B:D,2,0),0) -> 46 | H139: =IFERROR(VLOOKUP(B139,'6-week1'!B:D,3,0),"-") -> 25 | I139: =IF(G139>179,5,IF(G139>149,4,IF(G139>119,3,IF(G139>89,2,IF(G139>59,1,IF(G139<=59,0)))))) -> 0 | J139: =IF(H139>39,1,IF(H139>32,2,IF(H139>26,3,IF(H139>20,4,IF(H139<=20,5))))) -> 4 | K139: =AVERAGE(I139:J139) -> 2 | L139: =IFERROR(VLOOKUP(B139,'6-week2'!B:D,2,0),0) -> 0 | M139: =IFERROR(VLOOKUP(B139,'6-week2'!B:D,3,0),0) -> 0 | N139: =IF(L139>179,5,IF(L139>149,4,IF(L139>119,3,IF(L139>89,2,IF(L139>59,1,IF(L139<=59,0)))))) -> 0 | O139: =IF(M139>39,1,IF(M139>32,2,IF(M139>26,3,IF(M139>20,4,IF(M139<=20,5))))) -> 5 | P139: =AVERAGE(N139,O139) -> 2.5 | Q139: =IFERROR(VLOOKUP(B139,'6-week1'!B:F,5,0),0) -> 0
A140: امیرمحمد بادکوبه | B140: =TRIM(A140) -> امیرمحمد بادکوبه | C140: =VLOOKUP(B140,Company!B:E,3,0) -> سینا | D140: =VLOOKUP(B140,Company!B:E,2,0) -> صبح | E140: {=IFERROR(INDEX('Team Leads'!$B:$D, MATCH(C140,'Team Leads'!$A:$A,0), MATCH(D140,'Team Leads'!$B$1:$D$1,0)), "")} -> فاطمه دهقانپور | F140: =VLOOKUP(B140,'Operator Bugs'!A:P,16,0) -> 0 | G140: =IFERROR(VLOOKUP(B140,'6-week1'!B:D,2,0),0) -> 61 | H140: =IFERROR(VLOOKUP(B140,'6-week1'!B:D,3,0),"-") -> 32 | I140: =IF(G140>179,5,IF(G140>149,4,IF(G140>119,3,IF(G140>89,2,IF(G140>59,1,IF(G140<=59,0)))))) -> 1 | J140: =IF(H140>39,1,IF(H140>32,2,IF(H140>26,3,IF(H140>20,4,IF(H140<=20,5))))) -> 3 | K140: =AVERAGE(I140:J140) -> 2 | L140: =IFERROR(VLOOKUP(B140,'6-week2'!B:D,2,0),0) -> 106 | M140: =IFERROR(VLOOKUP(B140,'6-week2'!B:D,3,0),0) -> 26 | N140: =IF(L140>179,5,IF(L140>149,4,IF(L140>119,3,IF(L140>89,2,IF(L140>59,1,IF(L140<=59,0)))))) -> 2 | O140: =IF(M140>39,1,IF(M140>32,2,IF(M140>26,3,IF(M140>20,4,IF(M140<=20,5))))) -> 4 | P140: =AVERAGE(N140,O140) -> 3 | Q140: =IFERROR(VLOOKUP(B140,'6-week1'!B:F,5,0),0) -> 0
A141: حمید قربانی | B141: =TRIM(A141) -> حمید قربانی | C141: =VLOOKUP(B141,Company!B:E,3,0) -> سینا | D141: =VLOOKUP(B141,Company!B:E,2,0) -> عصر | E141: {=IFERROR(INDEX('Team Leads'!$B:$D, MATCH(C141,'Team Leads'!$A:$A,0), MATCH(D141,'Team Leads'!$B$1:$D$1,0)), "")} -> مهدی ایازی | F141: =VLOOKUP(B141,'Operator Bugs'!A:P,16,0) -> 0 | G141: =IFERROR(VLOOKUP(B141,'6-week1'!B:D,2,0),0) -> 42 | H141: =IFERROR(VLOOKUP(B141,'6-week1'!B:D,3,0),"-") -> 22 | I141: =IF(G141>179,5,IF(G141>149,4,IF(G141>119,3,IF(G141>89,2,IF(G141>59,1,IF(G141<=59,0)))))) -> 0 | J141: =IF(H141>39,1,IF(H141>32,2,IF(H141>26,3,IF(H141>20,4,IF(H141<=20,5))))) -> 4 | K141: =AVERAGE(I141:J141) -> 2 | L141: =IFERROR(VLOOKUP(B141,'6-week2'!B:D,2,0),0) -> 39 | M141: =IFERROR(VLOOKUP(B141,'6-week2'!B:D,3,0),0) -> 32 | N141: =IF(L141>179,5,IF(L141>149,4,IF(L141>119,3,IF(L141>89,2,IF(L141>59,1,IF(L141<=59,0)))))) -> 0 | O141: =IF(M141>39,1,IF(M141>32,2,IF(M141>26,3,IF(M141>20,4,IF(M141<=20,5))))) -> 3 | P141: =AVERAGE(N141,O141) -> 1.5 | Q141: =IFERROR(VLOOKUP(B141,'6-week1'!B:F,5,0),0) -> 0
A142: حنانه خیرالهی | B142: =TRIM(A142) -> حنانه خیرالهی | C142: =VLOOKUP(B142,Company!B:E,3,0) -> سینا | D142: =VLOOKUP(B142,Company!B:E,2,0) -> صبح | E142: {=IFERROR(INDEX('Team Leads'!$B:$D, MATCH(C142,'Team Leads'!$A:$A,0), MATCH(D142,'Team Leads'!$B$1:$D$1,0)), "")} -> فاطمه دهقانپور | F142: =VLOOKUP(B142,'Operator Bugs'!A:P,16,0) -> 0 | G142: =IFERROR(VLOOKUP(B142,'6-week1'!B:D,2,0),0) -> 28 | H142: =IFERROR(VLOOKUP(B142,'6-week1'!B:D,3,0),"-") -> 22 | I142: =IF(G142>179,5,IF(G142>149,4,IF(G142>119,3,IF(G142>89,2,IF(G142>59,1,IF(G142<=59,0)))))) -> 0 | J142: =IF(H142>39,1,IF(H142>32,2,IF(H142>26,3,IF(H142>20,4,IF(H142<=20,5))))) -> 4 | K142: =AVERAGE(I142:J142) -> 2 | L142: =IFERROR(VLOOKUP(B142,'6-week2'!B:D,2,0),0) -> 0 | M142: =IFERROR(VLOOKUP(B142,'6-week2'!B:D,3,0),0) -> 0 | N142: =IF(L142>179,5,IF(L142>149,4,IF(L142>119,3,IF(L142>89,2,IF(L142>59,1,IF(L142<=59,0)))))) -> 0 | O142: =IF(M142>39,1,IF(M142>32,2,IF(M142>26,3,IF(M142>20,4,IF(M142<=20,5))))) -> 5 | P142: =AVERAGE(N142,O142) -> 2.5 | Q142: =IFERROR(VLOOKUP(B142,'6-week1'!B:F,5,0),0) -> 0
A143: رویا نادرالوارس | B143: =TRIM(A143) -> رویا نادرالوارس | C143: =VLOOKUP(B143,Company!B:E,3,0) -> رازی | D143: =VLOOKUP(B143,Company!B:E,2,0) -> عصر | E143: {=IFERROR(INDEX('Team Leads'!$B:$D, MATCH(C143,'Team Leads'!$A:$A,0), MATCH(D143,'Team Leads'!$B$1:$D$1,0)), "")} -> امیررضا فلاح | F143: =VLOOKUP(B143,'Operator Bugs'!A:P,16,0) -> 0 | G143: =IFERROR(VLOOKUP(B143,'6-week1'!B:D,2,0),0) -> 69 | H143: =IFERROR(VLOOKUP(B143,'6-week1'!B:D,3,0),"-") -> 29 | I143: =IF(G143>179,5,IF(G143>149,4,IF(G143>119,3,IF(G143>89,2,IF(G143>59,1,IF(G143<=59,0)))))) -> 1 | J143: =IF(H143>39,1,IF(H143>32,2,IF(H143>26,3,IF(H143>20,4,IF(H143<=20,5))))) -> 3 | K143: =AVERAGE(I143:J143) -> 2 | L143: =IFERROR(VLOOKUP(B143,'6-week2'!B:D,2,0),0) -> 98 | M143: =IFERROR(VLOOKUP(B143,'6-week2'!B:D,3,0),0) -> 25 | N143: =IF(L143>179,5,IF(L143>149,4,IF(L143>119,3,IF(L143>89,2,IF(L143>59,1,IF(L143<=59,0)))))) -> 2 | O143: =IF(M143>39,1,IF(M143>32,2,IF(M143>26,3,IF(M143>20,4,IF(M143<=20,5))))) -> 4 | P143: =AVERAGE(N143,O143) -> 3 | Q143: =IFERROR(VLOOKUP(B143,'6-week1'!B:F,5,0),0) -> 0
...

Sheet Center Issue

Sheet Operator Bugs
A1: Operator name | B1: Non financial Bugs | G1: Financial Bugs | K1: Effective Bugs | M1: N.F.B count | N1: F.B count | O1: E.B count | P1: Total
A2: آبتین جباری | B2: =FALSE() -> FALSE | C2: =FALSE() -> FALSE | D2: =FALSE() -> FALSE | E2: =FALSE() -> FALSE | F2: =FALSE() -> FALSE | G2: =FALSE() -> FALSE | H2: =FALSE() -> FALSE | I2: =FALSE() -> FALSE | ... L2: =FALSE() -> FALSE | M2: =COUNTIF(B2:F2,TRUE()) -> 0 | N2: =COUNTIF(G2:J2,TRUE()) -> 0 | O2: =COUNTIF(K2:L2,TRUE()) -> 0 | P2: 0
A3: رویا زارعی | B3: =FALSE() -> FALSE | C3: =FALSE() -> FALSE | D3: =FALSE() -> FALSE | E3: =FALSE() -> FALSE | F3: =FALSE() -> FALSE | G3: =FALSE() -> FALSE | H3: =FALSE() -> FALSE | I3: =FALSE() -> FALSE | ... L3: =FALSE() -> FALSE | M3: =COUNTIF(B3:F3,TRUE()) -> 0 | N3: =COUNTIF(G3:J3,TRUE()) -> 0 | O3: =COUNTIF(K3:L3,TRUE()) -> 0 | P3: 0
A4: علی قناعتی | B4: =FALSE() -> FALSE | C4: =FALSE() -> FALSE | D4: =FALSE() -> FALSE | E4: =FALSE() -> FALSE | F4: =FALSE() -> FALSE | G4: =FALSE() -> FALSE | H4: =FALSE() -> FALSE | I4: =FALSE() -> FALSE | ... L4: =FALSE() -> FALSE | M4: =COUNTIF(B4:F4,TRUE()) -> 0 | N4: =COUNTIF(G4:J4,TRUE()) -> 0 | O4: =COUNTIF(K4:L4,TRUE()) -> 0 | P4: 0
A5: علیرضا حمید نیا | B5: =FALSE() -> FALSE | C5: =FALSE() -> FALSE | D5: =FALSE() -> FALSE | E5: =FALSE() -> FALSE | F5: =FALSE() -> FALSE | G5: =FALSE() -> FALSE | H5: =FALSE() -> FALSE | I5: =FALSE() -> FALSE | ... L5: =FALSE() -> FALSE | M5: =COUNTIF(B5:F5,TRUE()) -> 0 | N5: =COUNTIF(G5:J5,TRUE()) -> 0 | O5: =COUNTIF(K5:L5,TRUE()) -> 0 | P5: 0
A6: معراج عزیزی | B6: =FALSE() -> FALSE | C6: =FALSE() -> FALSE | D6: =FALSE() -> FALSE | E6: =FALSE() -> FALSE | F6: =FALSE() -> FALSE | G6: =FALSE() -> FALSE | H6: =FALSE() -> FALSE | I6: =FALSE() -> FALSE | ... L6: =FALSE() -> FALSE | M6: =COUNTIF(B6:F6,TRUE()) -> 0 | N6: =COUNTIF(G6:J6,TRUE()) -> 0 | O6: =COUNTIF(K6:L6,TRUE()) -> 0 | P6: 0
A7: افشین میرزاده | B7: =FALSE() -> FALSE | C7: =FALSE() -> FALSE | D7: =FALSE() -> FALSE | E7: =FALSE() -> FALSE | F7: =FALSE() -> FALSE | G7: =FALSE() -> FALSE | H7: =FALSE() -> FALSE | I7: =FALSE() -> FALSE | ... L7: =FALSE() -> FALSE | M7: =COUNTIF(B7:F7,TRUE()) -> 0 | N7: =COUNTIF(G7:J7,TRUE()) -> 0 | O7: =COUNTIF(K7:L7,TRUE()) -> 0 | P7: 0
A8: امیر حسین پزشک پور | B8: =FALSE() -> FALSE | C8: =FALSE() -> FALSE | D8: =FALSE() -> FALSE | E8: =FALSE() -> FALSE | F8: =FALSE() -> FALSE | G8: =FALSE() -> FALSE | H8: =FALSE() -> FALSE | I8: =FALSE() -> FALSE | ... L8: =FALSE() -> FALSE | M8: =COUNTIF(B8:F8,TRUE()) -> 0 | N8: =COUNTIF(G8:J8,TRUE()) -> 0 | O8: =COUNTIF(K8:L8,TRUE()) -> 0 | P8: 0
A9: امیر رضا نوروزی | B9: =FALSE() -> FALSE | C9: =FALSE() -> FALSE | D9: =FALSE() -> FALSE | E9: =FALSE() -> FALSE | F9: =FALSE() -> FALSE | G9: =FALSE() -> FALSE | H9: =FALSE() -> FALSE | I9: =FALSE() -> FALSE | ... L9: =FALSE() -> FALSE | M9: =COUNTIF(B9:F9,TRUE()) -> 0 | N9: =COUNTIF(G9:J9,TRUE()) -> 0 | O9: =COUNTIF(K9:L9,TRUE()) -> 0 | P9: 0
A10: سارا جاوری | B10: =FALSE() -> FALSE | C10: =FALSE() -> FALSE | D10: =FALSE() -> FALSE | E10: =FALSE() -> FALSE | F10: =FALSE() -> FALSE | G10: =FALSE() -> FALSE | H10: =FALSE() -> FALSE | I10: =FALSE() -> FALSE | ... L10: =FALSE() -> FALSE | M10: =COUNTIF(B10:F10,TRUE()) -> 0 | N10: =COUNTIF(G10:J10,TRUE()) -> 0 | O10: =COUNTIF(K10:L10,TRUE()) -> 0 | P10: 0
A11: سارا رسولی | B11: =FALSE() -> FALSE | C11: =FALSE() -> FALSE | D11: =FALSE() -> FALSE | E11: =FALSE() -> FALSE | F11: =FALSE() -> FALSE | G11: =FALSE() -> FALSE | H11: =FALSE() -> FALSE | I11: =FALSE() -> FALSE | ... L11: =FALSE() -> FALSE | M11: =COUNTIF(B11:F11,TRUE()) -> 0 | N11: =COUNTIF(G11:J11,TRUE()) -> 0 | O11: =COUNTIF(K11:L11,TRUE()) -> 0 | P11: 0
A12: فاطمه بهزادی | B12: =FALSE() -> FALSE | C12: =FALSE() -> FALSE | D12: =FALSE() -> FALSE | E12: =FALSE() -> FALSE | F12: =FALSE() -> FALSE | G12: =FALSE() -> FALSE | H12: =FALSE() -> FALSE | I12: =FALSE() -> FALSE | ... L12: =FALSE() -> FALSE | M12: =COUNTIF(B12:F12,TRUE()) -> 0 | N12: =COUNTIF(G12:J12,TRUE()) -> 0 | O12: =COUNTIF(K12:L12,TRUE()) -> 0 | P12: 0
A13: محمد سعیدیان | B13: =FALSE() -> FALSE | C13: =FALSE() -> FALSE | D13: =FALSE() -> FALSE | E13: =FALSE() -> FALSE | F13: =FALSE() -> FALSE | G13: =FALSE() -> FALSE | H13: =FALSE() -> FALSE | I13: =FALSE() -> FALSE | ... L13: =FALSE() -> FALSE | M13: =COUNTIF(B13:F13,TRUE()) -> 0 | N13: =COUNTIF(G13:J13,TRUE()) -> 0 | O13: =COUNTIF(K13:L13,TRUE()) -> 0 | P13: 0
... A283: مرکز صدور پیرهادی | نسترن محبی | B283: =FALSE() -> FALSE | C283: =FALSE() -> FALSE | D283: =FALSE() -> FALSE | E283: =FALSE() -> FALSE | F283: =FALSE() -> FALSE | G283: =FALSE() -> FALSE | H283: =FALSE() -> FALSE | I283: =FALSE() -> FALSE | ... L283: =FALSE() -> FALSE | M283: =COUNTIF(B283:F283,TRUE()) -> 0 | N283: =COUNTIF(G283:J283,TRUE()) -> 0 | O283: =COUNTIF(K283:L283,TRUE()) -> 0 | P283: 0
B284: =FALSE() -> FALSE | C284: =FALSE() -> FALSE | D284: =FALSE() -> FALSE | E284: =FALSE() -> FALSE | F284: =FALSE() -> FALSE | G284: =FALSE() -> FALSE | H284: =FALSE() -> FALSE | I284: =FALSE() -> FALSE | ... L284: =FALSE() -> FALSE | M284: =COUNTIF(B284:F284,TRUE()) -> 0 | N284: =COUNTIF(G284:J284,TRUE()) -> 0 | O284: =COUNTIF(K284:L284,TRUE()) -> 0 | P284: 0
B285: =FALSE() -> FALSE | C285: =FALSE() -> FALSE | D285: =FALSE() -> FALSE | E285: =FALSE() -> FALSE | F285: =FALSE() -> FALSE | G285: =FALSE() -> FALSE | H285: =FALSE() -> FALSE | I285: =FALSE() -> FALSE | ... L285: =FALSE() -> FALSE | M285: =COUNTIF(B285:F285,TRUE()) -> 0 | N285: =COUNTIF(G285:J285,TRUE()) -> 0 | O285: =COUNTIF(K285:L285,TRUE()) -> 0 | P285: 0
B286: =FALSE() -> FALSE | C286: =FALSE() -> FALSE | D286: =FALSE() -> FALSE | E286: =FALSE() -> FALSE | F286: =FALSE() -> FALSE | G286: =FALSE() -> FALSE | H286: =FALSE() -> FALSE | I286: =FALSE() -> FALSE | ... L286: =FALSE() -> FALSE | M286: =COUNTIF(B286:F286,TRUE()) -> 0 | N286: =COUNTIF(G286:J286,TRUE()) -> 0 | O286: =COUNTIF(K286:L286,TRUE()) -> 0 | P286: 0
B287: =FALSE() -> FALSE | C287: =FALSE() -> FALSE | D287: =FALSE() -> FALSE | E287: =FALSE() -> FALSE | F287: =FALSE() -> FALSE | G287: =FALSE() -> FALSE | H287: =FALSE() -> FALSE | I287: =FALSE() -> FALSE | ... L287: =FALSE() -> FALSE | M287: =COUNTIF(B287:F287,TRUE()) -> 0 | N287: =COUNTIF(G287:J287,TRUE()) -> 0 | O287: =COUNTIF(K287:L287,TRUE()) -> 0 | P287: 0
B288: =FALSE() -> FALSE | C288: =FALSE() -> FALSE | D288: =FALSE() -> FALSE | E288: =FALSE() -> FALSE | F288: =FALSE() -> FALSE | G288: =FALSE() -> FALSE | H288: =FALSE() -> FALSE | I288: =FALSE() -> FALSE | ... L288: =FALSE() -> FALSE | M288: =COUNTIF(B288:F288,TRUE()) -> 0 | N288: =COUNTIF(G288:J288,TRUE()) -> 0 | O288: =COUNTIF(K288:L288,TRUE()) -> 0 | P288: 0
B289: =FALSE() -> FALSE | C289: =FALSE() -> FALSE | D289: =FALSE() -> FALSE | E289: =FALSE() -> FALSE | F289: =FALSE() -> FALSE | G289: =FALSE() -> FALSE | H289: =FALSE() -> FALSE | I289: =FALSE() -> FALSE | ... L289: =FALSE() -> FALSE | M289: =COUNTIF(B289:F289,TRUE()) -> 0 | N289: =COUNTIF(G289:J289,TRUE()) -> 0 | O289: =COUNTIF(K289:L289,TRUE()) -> 0 | P289: 0
B290: =FALSE() -> FALSE | C290: =FALSE() -> FALSE | D290: =FALSE() -> FALSE | E290: =FALSE() -> FALSE | F290: =FALSE() -> FALSE | G290: =FALSE() -> FALSE | H290: =FALSE() -> FALSE | I290: =FALSE() -> FALSE | ... L290: =FALSE() -> FALSE | M290: =COUNTIF(B290:F290,TRUE()) -> 0 | N290: =COUNTIF(G290:J290,TRUE()) -> 0 | O290: =COUNTIF(K290:L290,TRUE()) -> 0 | P290: 0
B291: =FALSE() -> FALSE | C291: =FALSE() -> FALSE | D291: =FALSE() -> FALSE | E291: =FALSE() -> FALSE | F291: =FALSE() -> FALSE | G291: =FALSE() -> FALSE | H291: =FALSE() -> FALSE | I291: =FALSE() -> FALSE | ... L291: =FALSE() -> FALSE | M291: =COUNTIF(B291:F291,TRUE()) -> 0 | N291: =COUNTIF(G291:J291,TRUE()) -> 0 | O291: =COUNTIF(K291:L291,TRUE()) -> 0 | P291: 0
B292: =FALSE() -> FALSE | C292: =FALSE() -> FALSE | D292: =FALSE() -> FALSE | E292: =FALSE() -> FALSE | F292: =FALSE() -> FALSE | G292: =FALSE() -> FALSE | H292: =FALSE() -> FALSE | I292: =FALSE() -> FALSE | ... L292: =FALSE() -> FALSE | M292: =COUNTIF(B292:F292,TRUE()) -> 0 | N292: =COUNTIF(G292:J292,TRUE()) -> 0 | O292: =COUNTIF(K292:L292,TRUE()) -> 0 | P292: 0
B293: =FALSE() -> FALSE | C293: =FALSE() -> FALSE | D293: =FALSE() -> FALSE | E293: =FALSE() -> FALSE | F293: =FALSE() -> FALSE | G293: =FALSE() -> FALSE | H293: =FALSE() -> FALSE | I293: =FALSE() -> FALSE | ... L293: =FALSE() -> FALSE | M293: =COUNTIF(B293:F293,TRUE()) -> 0 | N293: =COUNTIF(G293:J293,TRUE()) -> 0 | O293: =COUNTIF(K293:L293,TRUE()) -> 0 | P293: 0
B294: =FALSE() -> FALSE | C294: =FALSE() -> FALSE | D294: =FALSE() -> FALSE | E294: =FALSE() -> FALSE | F294: =FALSE() -> FALSE | G294: =FALSE() -> FALSE | H294: =FALSE() -> FALSE | I294: =FALSE() -> FALSE | ... L294: =FALSE() -> FALSE | M294: =COUNTIF(B294:F294,TRUE()) -> 0 | N294: =COUNTIF(G294:J294,TRUE()) -> 0 | O294: =COUNTIF(K294:L294,TRUE()) -> 0 | P294: 0
